Workbook

Sheet 舰船数据-未改
A1: cid | B1: 舰种 | C1: 名称 | D1: 国籍 | E1: 耐久 | F1: 火力 | G1: 鱼雷 | H1: 装甲 | I1: 对空 | J1: 对潜 | K1: 命中 | L1: 回避 | M1: 索敌 | N1: 航速 | O1: 射程 | P1: 幸运 | Q1: 装备栏 | R1: 总搭载 | S1: 搭载1 | T1: 搭载2 | U1: 搭载3 | V1: 搭载4 | W1: 补给油耗 | X1: 补给弹耗 | Y1: 修理油耗 | Z1: 修理钢耗 | AA1: 技能1 | AB1: 技能2 | AC1: 标签
A2: 10022 | B2: CV | C2: 赤城 | D2: J | E2: 69 | F2: 40 | G2: 0 | H2: 55 | I2: 57 | J2: 0 | K2: 96 | L2: 52 | M2: 73 | N2: 31.2 | O2: 1 | P2: 10 | Q2: 4 | R2: =SUM($S2:$V2) -> 76 | S2: 21 | T2: 18 | U2: 27 | V2: 10 | W2: 60 | X2: 55 | Y2: 2.4 | Z2: 4.5
A3: 10023 | B3: CV | C3: 加贺 | D3: J | E3: 71 | F3: 40 | G3: 0 | H3: 62 | I3: 62 | J3: 0 | K3: 96 | L3: 48 | M3: 70 | N3: 28 | O3: 1 | P3: 13 | Q3: 4 | R3: =SUM($S3:$V3) -> 90 | S3: 17 | T3: 18 | U3: 43 | V3: 12 | W3: 60 | X3: 55 | Y3: 2.56 | Z3: 4.8
A4: 10029 | B4: CV | C4: 列克星敦 | D4: U | E4: 63 | F4: 35 | G4: 0 | H4: 65 | I4: 67 | J4: 0 | K4: 95 | L4: 52 | M4: 69 | N4: 33.2 | O4: 1 | P4: 20 | Q4: 4 | R4: =SUM($S4:$V4) -> 80 | S4: 20 | T4: 20 | U4: 30 | V4: 10 | W4: 55 | X4: 60 | Y4: 2.08 | Z4: 3.9
A5: 10030 | B5: CV | C5: 萨拉托加 | D5: U | E5: 63 | F5: 35 | G5: 0 | H5: 65 | I5: 85 | J5: 0 | K5: 95 | L5: 52 | M5: 69 | N5: 33.2 | O5: 1 | P5: 22 | Q5: 4 | R5: =SUM($S5:$V5) -> 80 | S5: 20 | T5: 20 | U5: 30 | V5: 10 | W5: 55 | X5: 60 | Y5: 2.08 | Z5: 3.9
A6: 10031 | B6: CV | C6: 大黄蜂 | D6: U | E6: 52 | F6: 40 | G6: 0 | H6: 57 | I6: 72 | J6: 0 | K6: 95 | L6: 52 | M6: 65 | N6: 32.5 | O6: 1 | P6: 10 | Q6: 4 | R6: =SUM($S6:$V6) -> 75 | S6: 21 | T6: 21 | U6: 23 | V6: 10 | W6: 55 | X6: 60 | Y6: 2.08 | Z6: 3.9
A7: 10100 | B7: BB | C7: 狮 | D7: E | E7: 81 | F7: 110 | G7: 0 | H7: 105 | I7: 85 | J7: 0 | K7: 97 | L7: 50 | M7: 42 | N7: 28.25 | O7: 3 | P7: 10 | Q7: 4 | R7: =SUM($S7:$V7) -> 8 | S7: 2 | T7: 2 | U7: 2 | V7: 2 | W7: 125 | X7: 175 | Y7: 4.8 | Z7: 9 | AA7: 111001 | AC7: lion
A8: 10105 | B8: BB | C8: 前卫 | D8: E | E8: 85 | F8: 90 | G8: 0 | H8: 96 | I8: 105 | J8: 0 | K8: 96 | L8: 49 | M8: 45 | N8: 30 | O8: 3 | P8: 15 | Q8: 4 | R8: =SUM($S8:$V8) -> 0 | S8: 0 | T8: 0 | U8: 0 | V8: 0 | W8: 90 | X8: 140 | Y8: 4.2 | Z8: 8 | AA8: 111052
A9: 10113 | B9: BB | C9: 黎塞留 | D9: F | E9: 78 | F9: 96 | G9: 0 | H9: 102 | I9: 60 | J9: 0 | K9: 96 | L9: 51 | M9: 40 | N9: 32 | O9: 3 | P9: 23 | Q9: 4 | R9: =SUM($S9:$V9) -> 12 | S9: 3 | T9: 3 | U9: 3 | V9: 3 | W9: 90 | X9: 130 | Y9: 4.2 | Z9: 8 | AA9: 111131
A10: 10117 | B10: AV | C10: 大凤 | D10: J | E10: 67 | F10: 40 | G10: 0 | H10: 85 | I10: 70 | J10: 0 | K10: 85 | L10: 57 | M10: 72 | N10: 33 | O10: 1 | P10: 5 | Q10: 4 | R10: =SUM($S10:$V10) -> 60 | S10: 18 | T10: 24 | U10: 12 | V10: 6 | W10: 70 | X10: 65 | Y10: 2.88 | Z10: 5.4 | AA10: 111171
A11: 10118 | B11: CV | C11: 齐柏林伯爵 | D11: G | E11: 52 | F11: 35 | G11: 0 | H11: 58 | I11: 66 | J11: 0 | K11: 95 | L11: 54 | M11: 65 | N11: 35 | O11: 1 | P11: 6 | Q11: 4 | R11: =SUM($S11:$V11) -> 48 | S11: 12 | T11: 15 | U11: 15 | V11: 6 | W11: 50 | X11: 55 | Y11: 2.08 | Z11: 4.3
A12: 10119 | B12: CV | C12: 皇家方舟 | D12: E | E12: 48 | F12: 40 | G12: 0 | H12: 61 | I12: 77 | J12: 0 | K12: 96 | L12: 51 | M12: 67 | N12: 31 | O12: 1 | P12: 15 | Q12: 4 | R12: =SUM($S12:$V12) -> 72 | S12: 18 | T12: 18 | U12: 24 | V12: 12 | W12: 50 | X12: 60 | Y12: 2.08 | Z12: 3.9 | AA12: 101191
A13: 10120 | B13: CV | C13: 约克城 | D13: U | E13: 50 | F13: 40 | G13: 0 | H13: 55 | I13: 68 | J13: 0 | K13: 95 | L13: 52 | M13: 65 | N13: 32.5 | O13: 1 | P13: 12 | Q13: 4 | R13: =SUM($S13:$V13) -> 75 | S13: 21 | T13: 21 | U13: 23 | V13: 10 | W13: 55 | X13: 60 | Y13: 2.08 | Z13: 3.9
A14: 10121 | B14: CV | C14: 企业 | D14: U | E14: 50 | F14: 45 | G14: 0 | H14: 55 | I14: 70 | J14: 0 | K14: 96 | L14: 52 | M14: 73 | N14: 32.5 | O14: 1 | P14: 55 | Q14: 4 | R14: =SUM($S14:$V14) -> 75 | S14: 21 | T14: 21 | U14: 23 | V14: 10 | W14: 55 | X14: 60 | Y14: 2.08 | Z14: 3.9 | AA14: 111211
A15: 10189 | B15: BC | C15: 天城 | D15: J | E15: 80 | F15: 115 | G15: 0 | H15: 90 | I15: 50 | J15: 0 | K15: 96 | L15: 49 | M15: 42 | N15: 30 | O15: 3 | P15: 6 | Q15: 4 | R15: =SUM($S15:$V15) -> 0 | S15: 0 | T15: 0 | U15: 0 | V15: 0 | W15: 100 | X15: 130 | Y15: 3.2 | Z15: 5.8 | AA15: 101891
A16: 10190 | B16: BB | C16: 土佐 | D16: J | E16: 80 | F16: 115 | G16: 0 | H16: 93 | I16: 51 | J16: 0 | K16: 96 | L16: 44 | M16: 42 | N16: 26.5 | O16: 3 | P16: 7 | Q16: 4 | R16: =SUM($S16:$V16) -> 0 | S16: 0 | T16: 0 | U16: 0 | V16: 0 | W16: 100 | X16: 130 | Y16: 3.2 | Z16: 5.8 | AA16: 101901
A17: 10191 | B17: BB | C17: A150 | D17: J | E17: 104 | F17: 128 | G17: 0 | H17: 120 | I17: 73 | J17: 0 | K17: 100 | L17: 44 | M17: 45 | N17: 28 | O17: 3 | P17: 5 | Q17: 4 | R17: =SUM($S17:$V17) -> 0 | S17: 0 | T17: 0 | U17: 0 | V17: 0 | W17: 170 | X17: 200 | Y17: 6 | Z17: 11 | AA17: 101911
A18: 10200 | B18: BB | C18: 兴登堡 | D18: G | E18: 100 | F18: 109 | G18: 0 | H18: 100 | I18: 66 | J18: 0 | K18: 97 | L18: 48 | M18: 43 | N18: 30 | O18: 3 | P18: 5 | Q18: 4 | R18: =SUM($S18:$V18) -> 16 | S18: 4 | T18: 4 | U18: 4 | V18: 4 | W18: 125 | X18: 165 | Y18: 4.8 | Z18: 9.9 | AA18: 102001
A19: 10201 | B19: BB | C19: V方案 | D19: Ar | E19: 76 | F19: 112 | G19: 0 | H19: 92 | I19: 55 | J19: 0 | K19: 100 | L19: 48 | M19: 38 | N19: 24 | O19: 3 | P19: 5 | Q19: 4 | R19: =SUM($S19:$V19) -> 0 | S19: 0 | T19: 0 | U19: 0 | V19: 0 | W19: 85 | X19: 130 | Y19: 4.1 | Z19: 8 | AA19: 102011
A20: 10202 | B20: BB | C20: 伊利诺伊 | D20: U | E20: 84 | F20: 116 | G20: 0 | H20: 106 | I20: 110 | J20: 0 | K20: 102 | L20: 52 | M20: 49 | N20: 33 | O20: 3 | P20: 6 | Q20: 4 | R20: =SUM($S20:$V20) -> 12 | S20: 3 | T20: 3 | U20: 3 | V20: 3 | W20: 135 | X20: 175 | Y20: 4.8 | Z20: 9 | AA20: 102021 | AC20: iowa
A21: 10205 | B21: BB | C21: 约克公爵 | D21: E | E21: 74 | F21: 95 | G21: 0 | H21: 95 | I21: 85 | J21: 0 | K21: 96 | L21: 48 | M21: 42 | N21: 29 | O21: 3 | P21: 18 | Q21: 4 | R21: =SUM($S21:$V21) -> 16 | S21: 4 | T21: 4 | U21: 4 | V21: 4 | W21: 90 | X21: 140 | Y21: 4.2 | Z21: 8 | AA21: 102051
A22: 10206 | B22: BB | C22: 北卡罗来纳 | D22: U | E22: 74 | F22: 108 | G22: 0 | H22: 92 | I22: 90 | J22: 0 | K22: 96 | L22: 47 | M22: 45 | N22: 28 | O22: 3 | P22: 25 | Q22: 4 | R22: =SUM($S22:$V22) -> 12 | S22: 3 | T22: 3 | U22: 3 | V22: 3 | W22: 95 | X22: 140 | Y22: 4.2 | Z22: 8 | AA22: 112061
A23: 10207 | B23: BB | C23: 南达科他 | D23: U | E23: 75 | F23: 108 | G23: 0 | H23: 100 | I23: 93 | J23: 0 | K23: 96 | L23: 46 | M23: 44 | N23: 27.5 | O23: 3 | P23: 13 | Q23: 4 | R23: =SUM($S23:$V23) -> 12 | S23: 3 | T23: 3 | U23: 3 | V23: 3 | W23: 95 | X23: 140 | Y23: 4.2 | Z23: 8 | AA23: 112071 | AC23: south_dakota
A24: 10208 | B24: BB | C24: 马萨诸塞 | D24: U | E24: 75 | F24: 108 | G24: 0 | H24: 100 | I24: 96 | J24: 0 | K24: 96 | L24: 46 | M24: 44 | N24: 27.5 | O24: 3 | P24: 24 | Q24: 4 | R24: =SUM($S24:$V24) -> 12 | S24: 3 | T24: 3 | U24: 3 | V24: 3 | W24: 95 | X24: 140 | Y24: 4.2 | Z24: 8 | AA24: 102081 | AC24: south_dakota
A25: 10209 | B25: BB | C25: 密苏里 | D25: U | E25: 84 | F25: 116 | G25: 0 | H25: 102 | I25: 108 | J25: 0 | K25: 102 | L25: 52 | M25: 47 | N25: 33 | O25: 3 | P25: 24 | Q25: 4 | R25: =SUM($S25:$V25) -> 12 | S25: 3 | T25: 3 | U25: 3 | V25: 3 | W25: 135 | X25: 175 | Y25: 4.8 | Z25: 9 | AA25: 102091 | AC25: iowa
A26: 10210 | B26: BB | C26: 衣阿华 | D26: U | E26: 84 | F26: 116 | G26: 0 | H26: 102 | I26: 106 | J26: 0 | K26: 102 | L26: 52 | M26: 45 | N26: 33 | O26: 3 | P26: 24 | Q26: 4 | R26: =SUM($S26:$V26) -> 12 | S26: 3 | T26: 3 | U26: 3 | V26: 3 | W26: 135 | X26: 175 | Y26: 4.8 | Z26: 9 | AA26: 102101 | AC26: iowa
A27: 10212 | B27: BB | C27: 利托里奥 | D27: I | E27: 75 | F27: 101 | G27: 0 | H27: 98 | I27: 63 | J27: 0 | K27: 96 | L27: 50 | M27: 41 | N27: 31 | O27: 3 | P27: 17 | Q27: 4 | R27: =SUM($S27:$V27) -> 12 | S27: 3 | T27: 3 | U27: 3 | V27: 3 | W27: 90 | X27: 130 | Y27: 4.2 | Z27: 8 | AA27: 102121 | AC27: veneto
A28: 10213 | B28: BB | C28: 罗马 | D28: I | E28: 75 | F28: 101 | G28: 0 | H28: 98 | I28: 65 | J28: 0 | K28: 96 | L28: 50 | M28: 41 | N28: 31 | O28: 3 | P28: 10 | Q28: 4 | R28: =SUM($S28:$V28) -> 12 | S28: 3 | T28: 3 | U28: 3 | V28: 3 | W28: 90 | X28: 130 | Y28: 4.2 | Z28: 8 | AA28: 102131 | AC28: veneto
A29: 10214 | B29: BB | C29: 苏联 | D29: S | E29: 92 | F29: 111 | G29: 0 | H29: 97 | I29: 67 | J29: 0 | K29: 96 | L29: 51 | M29: 38 | N29: 28 | O29: 3 | P29: 8 | Q29: 4 | R29: =SUM($S29:$V29) -> 16 | S29: 4 | T29: 4 | U29: 4 | V29: 4 | W29: 125 | X29: 165 | Y29: 4.8 | Z29: 9 | AA29: 102141
A30: 10219 | B30: CV | C30: 瑞鹤 | D30: J | E30: 62 | F30: 40 | G30: 0 | H30: 56 | I30: 66 | J30: 0 | K30: 96 | L30: 62 | M30: 73 | N30: 34.2 | O30: 1 | P30: 40 | Q30: 4 | R30: =SUM($S30:$V30) -> 78 | S30: 19 | T30: 26 | U30: 21 | V30: 12 | W30: 60 | X30: 55 | Y30: 2.4 | Z30: 4.5
A31: 10220 | B31: CV | C31: 翔鹤 | D31: J | E31: 62 | F31: 40 | G31: 0 | H31: 56 | I31: 66 | J31: 0 | K31: 96 | L31: 57 | M31: 73 | N31: 34.2 | O31: 1 | P31: 10 | Q31: 4 | R31: =SUM($S31:$V31) -> 78 | S31: 19 | T31: 26 | U31: 21 | V31: 12 | W31: 60 | X31: 55 | Y31: 2.4 | Z31: 4.5
A32: 10221 | B32: CV | C32: 飞龙 | D32: J | E32: 48 | F32: 40 | G32: 0 | H32: 52 | I32: 60 | J32: 0 | K32: 95 | L32: 57 | M32: 65 | N32: 34.5 | O32: 1 | P32: 13 | Q32: 4 | R32: =SUM($S32:$V32) -> 63 | S32: 21 | T32: 18 | U32: 18 | V32: 6 | W32: 60 | X32: 55 | Y32: 2.4 | Z32: 4.5
A33: 10222 | B33: CV | C33: 苍龙 | D33: J | E33: 46 | F33: 35 | G33: 0 | H33: 50 | I33: 55 | J33: 0 | K33: 95 | L33: 57 | M33: 69 | N33: 34.5 | O33: 1 | P33: 10 | Q33: 4 | R33: =SUM($S33:$V33) -> 63 | S33: 21 | T33: 18 | U33: 18 | V33: 6 | W33: 60 | X33: 55 | Y33: 2.4 | Z33: 4.5
A34: 10223 | B34: AV | C34: 信浓 | D34: J | E34: 96 | F34: 45 | G34: 0 | H34: 105 | I34: 68 | J34: 0 | K34: 86 | L34: 47 | M34: 74 | N34: 27 | O34: 1 | P34: 1 | Q34: 4 | R34: =SUM($S34:$V34) -> 59 | S34: 12 | T34: 12 | U34: 35 | V34: 0 | W34: 110 | X34: 100 | Y34: 3.5 | Z34: 6 | AA34: 112231
A35: 10224 | B35: AV | C35: 可畏 | D35: E | E35: 66 | F35: 40 | G35: 0 | H35: 93 | I35: 85 | J35: 0 | K35: 85 | L35: 56 | M35: 69 | N35: 30.5 | O35: 1 | P35: 22 | Q35: 4 | R35: =SUM($S35:$V35) -> 57 | S35: 10 | T35: 24 | U35: 15 | V35: 8 | W35: 70 | X35: 65 | Y35: 2.88 | Z35: 5.6 | AA35: 102241
A36: 10225 | B36: CV | C36: 黄蜂 | D36: U | E36: 37 | F36: 35 | G36: 0 | H36: 45 | I36: 65 | J36: 0 | K36: 95 | L36: 49 | M36: 67 | N36: 29.5 | O36: 1 | P36: 9 | Q36: 4 | R36: =SUM($S36:$V36) -> 70 | S36: 15 | T36: 15 | U36: 25 | V36: 15 | W36: 55 | X36: 60 | Y36: 2.08 | Z36: 3.9
A37: 10226 | B37: CV | C37: 埃塞克斯 | D37: U | E37: 60 | F37: 40 | G37: 0 | H37: 60 | I37: 90 | J37: 0 | K37: 96 | L37: 52 | M37: 77 | N37: 33 | O37: 1 | P37: 20 | Q37: 4 | R37: =SUM($S37:$V37) -> 90 | S37: 18 | T37: 18 | U37: 36 | V37: 18 | W37: 60 | X37: 60 | Y37: 2.4 | Z37: 4.5 | AA37: 102261 | AC37: essex
A38: 10231 | B38: CV | C38: 伦道夫 | D38: U | E38: 60 | F38: 40 | G38: 0 | H38: 60 | I38: 92 | J38: 0 | K38: 96 | L38: 52 | M38: 77 | N38: 33 | O38: 1 | P38: 20 | Q38: 4 | R38: =SUM($S38:$V38) -> 90 | S38: 18 | T38: 18 | U38: 36 | V38: 18 | W38: 60 | X38: 60 | Y38: 2.4 | Z38: 4.5 | AA38: 102311 | AC38: essex
A39: 10232 | B39: CV | C39: 贝亚恩 | D39: F | E39: 62 | F39: 35 | G39: 0 | H39: 59 | I39: 59 | J39: 0 | K39: 94 | L39: 41 | M39: 59 | N39: 21.5 | O39: 1 | P39: 16 | Q39: 4 | R39: =SUM($S39:$V39) -> 40 | S39: 12 | T39: 12 | U39: 12 | V39: 4 | W39: 50 | X39: 55 | Y39: 2.08 | Z39: 3.9
A40: 10241 | B40: CA | C40: 巴尔的摩 | D40: U | E40: 52 | F40: 68 | G40: 0 | H40: 56 | I40: 90 | J40: 0 | K40: 93 | L40: 75 | M40: 56 | N40: 33 | O40: 2 | P40: 17 | Q40: 3 | R40: =SUM($S40:$V40) -> 6 | S40: 2 | T40: 2 | U40: 2 | V40: 0 | W40: 40 | X40: 70 | Y40: 1.28 | Z40: 2.4 | AA40: 112411
...

Sheet 舰船数据-改造
A1: cid | B1: 舰种 | C1: 名称 | D1: 国籍 | E1: 耐久 | F1: 火力 | G1: 鱼雷 | H1: 装甲 | I1: 对空 | J1: 对潜 | K1: 命中 | L1: 回避 | M1: 索敌 | N1: 航速 | O1: 射程 | P1: 幸运 | Q1: 装备栏 | R1: 总搭载 | S1: 搭载1 | T1: 搭载2 | U1: 搭载3 | V1: 搭载4 | W1: 补给油耗 | X1: 补给弹耗 | Y1: 修理油耗 | Z1: 修理钢耗 | AA1: 技能1 | AB1: 技能2 | AC1: 标签
A2: 11001 | B2: BC | C2: 胡德 | D2: E | E2: 80 | F2: 103 | G2: 0 | H2: 87 | I2: 85 | J2: 0 | K2: 102 | L2: 68 | M2: 45 | N2: 32 | O2: 3 | P2: 8 | Q2: 4 | R2: =SUM($S2:$V2) -> 12 | S2: 3 | T2: 3 | U2: 3 | V2: 3 | W2: 70 | X2: 120 | Y2: 2.88 | Z2: 5.4 | AA2: 110011 | AB2: 110012
A3: 11002 | B3: BBV | C3: 扶桑 | D3: J | E3: 72 | F3: 88 | G3: 0 | H3: 84 | I3: 67 | J3: 0 | K3: 100 | L3: 52 | M3: 47 | N3: 24 | O3: 3 | P3: 9 | Q3: 4 | R3: =SUM($S3:$V3) -> 30 | S3: 0 | T3: 0 | U3: 12 | V3: 18 | W3: 85 | X3: 120 | Y3: 2.5 | Z3: 5.1 | AA3: 110021
A4: 11003 | B4: BB | C4: 山城 | D4: J | E4: 72 | F4: 107 | G4: 0 | H4: 84 | I4: 50 | J4: 0 | K4: 97 | L4: 49 | M4: 37 | N4: 23 | O4: 3 | P4: 9 | Q4: 4 | R4: =SUM($S4:$V4) -> 8 | S4: 2 | T4: 2 | U4: 2 | V4: 2 | W4: 85 | X4: 135 | Y4: 2.5 | Z4: 5.2 | AA4: 110021
A5: 11004 | B5: BBV | C5: 伊势 | D5: J | E5: 79 | F5: 87 | G5: 0 | H5: 87 | I5: 78 | J5: 0 | K5: 100 | L5: 53 | M5: 47 | N5: 24.5 | O5: 3 | P5: 15 | Q5: 4 | R5: =SUM($S5:$V5) -> 24 | S5: 0 | T5: 0 | U5: 12 | V5: 12 | W5: 85 | X5: 120 | Y5: 2.5 | Z5: 5.1 | AA5: 110041
A6: 11005 | B6: BBV | C6: 日向 | D6: J | E6: 79 | F6: 87 | G6: 0 | H6: 87 | I6: 78 | J6: 0 | K6: 100 | L6: 53 | M6: 47 | N6: 24.5 | O6: 3 | P6: 15 | Q6: 4 | R6: =SUM($S6:$V6) -> 24 | S6: 0 | T6: 0 | U6: 12 | V6: 12 | W6: 85 | X6: 120 | Y6: 2.5 | Z6: 5.1 | AA6: 110051
A7: 11006 | B7: BB | C7: 俾斯麦 | D7: G | E7: 100 | F7: 102 | G7: 0 | H7: 100 | I7: 67 | J7: 0 | K7: 102 | L7: 55 | M7: 49 | N7: 30.8 | O7: 3 | P7: 18 | Q7: 4 | R7: =SUM($S7:$V7) -> 16 | S7: 4 | T7: 4 | U7: 4 | V7: 4 | W7: 90 | X7: 130 | Y7: 4.2 | Z7: 8.8 | AA7: 110061 | AB7: 110062
A8: 11007 | B8: BB | C8: 提尔比茨 | D8: G | E8: 101 | F8: 102 | G8: 30 | H8: 100 | I8: 69 | J8: 0 | K8: 102 | L8: 55 | M8: 49 | N8: 30 | O8: 3 | P8: 16 | Q8: 4 | R8: =SUM($S8:$V8) -> 16 | S8: 4 | T8: 4 | U8: 4 | V8: 4 | W8: 90 | X8: 130 | Y8: 4.2 | Z8: 8.8 | AA8: 110071
A9: 11008 | B9: BB | C9: 纳尔逊 | D9: E | E9: 77 | F9: 109 | G9: 0 | H9: 102 | I9: 77 | J9: 0 | K9: 101 | L9: 48 | M9: 43 | N9: 23.5 | O9: 3 | P9: 20 | Q9: 4 | R9: =SUM($S9:$V9) -> 0 | S9: 0 | T9: 0 | U9: 0 | V9: 0 | W9: 90 | X9: 140 | Y9: 3.2 | Z9: 6 | AA9: 110081 | AC9: big_seven
A10: 11009 | B10: BB | C10: 罗德尼 | D10: E | E10: 76 | F10: 109 | G10: 0 | H10: 102 | I10: 77 | J10: 0 | K10: 101 | L10: 48 | M10: 43 | N10: 23.5 | O10: 3 | P10: 20 | Q10: 4 | R10: =SUM($S10:$V10) -> 8 | S10: 2 | T10: 2 | U10: 2 | V10: 2 | W10: 90 | X10: 140 | Y10: 3.2 | Z10: 6 | AA10: 110081 | AB10: 110092 | AC10: big_seven
A11: 11010 | B11: BB | C11: 威尔士亲王 | D11: E | E11: 79 | F11: 100 | G11: 0 | H11: 100 | I11: 92 | J11: 0 | K11: 102 | L11: 55 | M11: 45 | N11: 29 | O11: 3 | P11: 10 | Q11: 4 | R11: =SUM($S11:$V11) -> 16 | S11: 4 | T11: 4 | U11: 4 | V11: 4 | W11: 90 | X11: 140 | Y11: 4.2 | Z11: 8 | AA11: 110101 | AB11: 110102
A12: 11011 | B12: BB | C12: 内华达 | D12: U | E12: 72 | F12: 90 | G12: 0 | H12: 93 | I12: 97 | J12: 0 | K12: 100 | L12: 44 | M12: 42 | N12: 21 | O12: 3 | P12: 30 | Q12: 4 | R12: =SUM($S12:$V12) -> 12 | S12: 3 | T12: 3 | U12: 3 | V12: 3 | W12: 85 | X12: 125 | Y12: 2.5 | Z12: 5.1 | AA12: 110111
A13: 11012 | B13: BB | C13: 俄克拉荷马 | D13: U | E13: 72 | F13: 90 | G13: 0 | H13: 93 | I13: 97 | J13: 0 | K13: 100 | L13: 44 | M13: 42 | N13: 21 | O13: 3 | P13: 10 | Q13: 4 | R13: =SUM($S13:$V13) -> 12 | S13: 3 | T13: 3 | U13: 3 | V13: 3 | W13: 85 | X13: 125 | Y13: 2.5 | Z13: 5.1 | AA13: 110111
A14: 11013 | B14: BB | C14: 安德烈亚·多利亚 | D14: I | E14: 64 | F14: 89 | G14: 0 | H14: 89 | I14: 70 | J14: 0 | K14: 102 | L14: 63 | M14: 40 | N14: 27 | O14: 3 | P14: 20 | Q14: 4 | R14: =SUM($S14:$V14) -> 12 | S14: 3 | T14: 3 | U14: 3 | V14: 3 | W14: 70 | X14: 110 | Y14: 2.25 | Z14: 4.55 | AA14: 110131
A15: 11014 | B15: BB | C15: 金刚 | D15: J | E15: 68 | F15: 96 | G15: 0 | H15: 73 | I15: 67 | J15: 0 | K15: 100 | L15: 72 | M15: 45 | N15: 30.3 | O15: 3 | P15: 15 | Q15: 4 | R15: =SUM($S15:$V15) -> 12 | S15: 3 | T15: 3 | U15: 3 | V15: 3 | W15: 80 | X15: 110 | Y15: 2.88 | Z15: 5.4 | AA15: 110141
A16: 11018 | B16: BC | C16: 声望 | D16: E | E16: 70 | F16: 93 | G16: 0 | H16: 80 | I16: 97 | J16: 0 | K16: 101 | L16: 71 | M16: 44 | N16: 31.5 | O16: 3 | P16: 35 | Q16: 4 | R16: =SUM($S16:$V16) -> 16 | S16: 4 | T16: 4 | U16: 4 | V16: 4 | W16: 70 | X16: 120 | Y16: 2.88 | Z16: 5.4 | AA16: 110181 | AB16: 110182
A17: 11019 | B17: BC | C17: 反击 | D17: E | E17: 70 | F17: 88 | G17: 0 | H17: 78 | I17: 75 | J17: 0 | K17: 100 | L17: 74 | M17: 41 | N17: 31.5 | O17: 3 | P17: 12 | Q17: 4 | R17: =SUM($S17:$V17) -> 16 | S17: 4 | T17: 4 | U17: 4 | V17: 4 | W17: 70 | X17: 120 | Y17: 2.88 | Z17: 5.4 | AA17: 110191
A18: 11020 | B18: CBG | C18: 阿拉斯加 | D18: U | E18: 63 | F18: 90 | G18: 0 | H18: 73 | I18: 110 | J18: 0 | K18: 102 | L18: 72 | M18: 55 | N18: 33 | O18: 3 | P18: 15 | Q18: 4 | R18: =SUM($S18:$V18) -> 48 | S18: 12 | T18: 12 | U18: 12 | V18: 12 | W18: 85 | X18: 135 | Y18: 2.9 | Z18: 5.6 | AA18: 110201
A19: 11021 | B19: CBG | C19: 关岛 | D19: U | E19: 63 | F19: 95 | G19: 0 | H19: 72 | I19: 105 | J19: 0 | K19: 102 | L19: 72 | M19: 55 | N19: 33 | O19: 3 | P19: 15 | Q19: 4 | R19: =SUM($S19:$V19) -> 48 | S19: 12 | T19: 12 | U19: 12 | V19: 12 | W19: 85 | X19: 140 | Y19: 2.88 | Z19: 5.6 | AA19: 110211
A20: 11022 | B20: CV | C20: 赤城 | D20: J | E20: 79 | F20: 40 | G20: 0 | H20: 61 | I20: 62 | J20: 0 | K20: 102 | L20: 57 | M20: 77 | N20: 31.2 | O20: 1 | P20: 10 | Q20: 4 | R20: =SUM($S20:$V20) -> 86 | S20: 20 | T20: 20 | U20: 36 | V20: 10 | W20: 60 | X20: 55 | Y20: 2.4 | Z20: 4.5 | AA20: 110221 | AB20: 110222
A21: 11023 | B21: CV | C21: 加贺 | D21: J | E21: 81 | F21: 40 | G21: 0 | H21: 68 | I21: 67 | J21: 0 | K21: 102 | L21: 56 | M21: 75 | N21: 28 | O21: 1 | P21: 10 | Q21: 4 | R21: =SUM($S21:$V21) -> 95 | S21: 22 | T21: 18 | U21: 40 | V21: 15 | W21: 60 | X21: 55 | Y21: 2.56 | Z21: 4.8 | AA21: 110231 | AB21: 110232
A22: 11024 | B22: CVL | C22: 祥凤 | D22: J | E22: 47 | F22: 30 | G22: 0 | H22: 50 | I22: 53 | J22: 0 | K22: 96 | L22: 61 | M22: 63 | N22: 29 | O22: 1 | P22: 10 | Q22: 3 | R22: =SUM($S22:$V22) -> 39 | S22: 17 | T22: 13 | U22: 9 | V22: 0 | W22: 35 | X22: 35 | Y22: 1.28 | Z22: 2.4 | AA22: 110241
A23: 11025 | B23: CVL | C23: 瑞凤 | D23: J | E23: 47 | F23: 30 | G23: 0 | H23: 53 | I23: 58 | J23: 0 | K23: 96 | L23: 61 | M23: 63 | N23: 29 | O23: 1 | P23: 20 | Q23: 3 | R23: =SUM($S23:$V23) -> 37 | S23: 18 | T23: 13 | U23: 6 | V23: 0 | W23: 40 | X23: 35 | Y23: 1.28 | Z23: 2.4 | AA23: 110251
A24: 11026 | B24: CVL | C24: 百眼巨人 | D24: E | E24: 38 | F24: 25 | G24: 0 | H24: 35 | I24: 63 | J24: 0 | K24: 95 | L24: 47 | M24: 78 | N24: 20.7 | O24: 1 | P24: 20 | Q24: 3 | R24: =SUM($S24:$V24) -> 28 | S24: 8 | T24: 12 | U24: 8 | V24: 0 | W24: 20 | X24: 30 | Y24: 0.96 | Z24: 1.8
A25: 11027 | B25: CVL | C25: 兰利 | D25: U | E25: 39 | F25: 25 | G25: 0 | H25: 36 | I25: 72 | J25: 0 | K25: 95 | L25: 42 | M25: 80 | N25: 15 | O25: 1 | P25: 20 | Q25: 3 | R25: =SUM($S25:$V25) -> 35 | S25: 15 | T25: 10 | U25: 10 | V25: 0 | W25: 25 | X25: 30 | Y25: 0.96 | Z25: 1.8
A26: 11028 | B26: CV | C26: 突击者 | D26: U | E26: 48 | F26: 30 | G26: 0 | H26: 48 | I26: 65 | J26: 0 | K26: 100 | L26: 76 | M26: 88 | N26: 29.2 | O26: 1 | P26: 25 | Q26: 4 | R26: =SUM($S26:$V26) -> 65 | S26: 15 | T26: 20 | U26: 25 | V26: 5 | W26: 45 | X26: 50 | Y26: 1.68 | Z26: 3.2 | AA26: 110281
A27: 11029 | B27: CV | C27: 列克星敦 | D27: U | E27: 73 | F27: 40 | G27: 0 | H27: 74 | I27: 77 | J27: 0 | K27: 101 | L27: 58 | M27: 90 | N27: 33.2 | O27: 1 | P27: 20 | Q27: 4 | R27: =SUM($S27:$V27) -> 85 | S27: 20 | T27: 20 | U27: 35 | V27: 10 | W27: 55 | X27: 60 | Y27: 2.08 | Z27: 3.9 | AA27: 110291
A28: 11030 | B28: CV | C28: 萨拉托加 | D28: U | E28: 73 | F28: 40 | G28: 0 | H28: 74 | I28: 90 | J28: 0 | K28: 101 | L28: 58 | M28: 90 | N28: 33.2 | O28: 1 | P28: 32 | Q28: 4 | R28: =SUM($S28:$V28) -> 85 | S28: 20 | T28: 20 | U28: 35 | V28: 10 | W28: 55 | X28: 60 | Y28: 2.08 | Z28: 3.9 | AA28: 110291 | AB28: 110302
A29: 11031 | B29: CV | C29: 大黄蜂 | D29: U | E29: 60 | F29: 45 | G29: 0 | H29: 66 | I29: 80 | J29: 0 | K29: 101 | L29: 58 | M29: 65 | N29: 32.5 | O29: 1 | P29: 12 | Q29: 4 | R29: =SUM($S29:$V29) -> 87 | S29: 15 | T29: 25 | U29: 36 | V29: 11 | W29: 55 | X29: 70 | Y29: 2.08 | Z29: 3.9 | AA29: 110311
A30: 11032 | B30: CA | C30: 高雄 | D30: J | E30: 55 | F30: 70 | G30: 72 | H30: 53 | I30: 58 | J30: 0 | K30: 97 | L30: 89 | M30: 58 | N30: 35 | O30: 2 | P30: 10 | Q30: 4 | R30: =SUM($S30:$V30) -> 6 | S30: 2 | T30: 2 | U30: 2 | V30: 0 | W30: 40 | X30: 65 | Y30: 1.28 | Z30: 2.4 | AA30: 110321
A31: 11033 | B31: CA | C31: 爱宕 | D31: J | E31: 55 | F31: 70 | G31: 72 | H31: 53 | I31: 58 | J31: 0 | K31: 97 | L31: 89 | M31: 58 | N31: 35 | O31: 2 | P31: 10 | Q31: 4 | R31: =SUM($S31:$V31) -> 6 | S31: 2 | T31: 2 | U31: 2 | V31: 0 | W31: 40 | X31: 65 | Y31: 1.28 | Z31: 2.4 | AA31: 110331
A32: 11034 | B32: CA | C32: 摩耶 | D32: J | E32: 55 | F32: 68 | G32: 72 | H32: 52 | I32: 67 | J32: 0 | K32: 97 | L32: 89 | M32: 58 | N32: 35 | O32: 2 | P32: 10 | Q32: 4 | R32: =SUM($S32:$V32) -> 6 | S32: 2 | T32: 2 | U32: 2 | V32: 0 | W32: 40 | X32: 65 | Y32: 1.28 | Z32: 2.4 | AA32: 110341
A33: 11035 | B33: CA | C33: 鸟海 | D33: J | E33: 55 | F33: 70 | G33: 72 | H33: 53 | I33: 55 | J33: 0 | K33: 97 | L33: 89 | M33: 58 | N33: 35 | O33: 2 | P33: 10 | Q33: 4 | R33: =SUM($S33:$V33) -> 6 | S33: 2 | T33: 2 | U33: 2 | V33: 0 | W33: 40 | X33: 65 | Y33: 1.28 | Z33: 2.4 | AA33: 110351
A34: 11036 | B34: CA | C34: 希佩尔海军上将 | D34: G | E34: 61 | F34: 69 | G34: 65 | H34: 50 | I34: 57 | J34: 0 | K34: 97 | L34: 82 | M34: 65 | N34: 32.5 | O34: 2 | P34: 15 | Q34: 4 | R34: =SUM($S34:$V34) -> 12 | S34: 3 | T34: 3 | U34: 3 | V34: 3 | W34: 35 | X34: 65 | Y34: 1.28 | Z34: 2.64 | AA34: 110361
A35: 11037 | B35: CA | C35: 布吕歇尔 | D35: G | E35: 62 | F35: 66 | G35: 65 | H35: 52 | I35: 57 | J35: 0 | K35: 97 | L35: 87 | M35: 62 | N35: 32.5 | O35: 2 | P35: 15 | Q35: 4 | R35: =SUM($S35:$V35) -> 12 | S35: 3 | T35: 3 | U35: 3 | V35: 3 | W35: 35 | X35: 65 | Y35: 1.28 | Z35: 2.64 | AA35: 110371
A36: 11038 | B36: CA | C36: 欧根亲王 | D36: G | E36: 69 | F36: 61 | G36: 55 | H36: 70 | I36: 65 | J36: 0 | K36: 99 | L36: 82 | M36: 68 | N36: 32 | O36: 2 | P36: 35 | Q36: 4 | R36: =SUM($S36:$V36) -> 12 | S36: 3 | T36: 3 | U36: 3 | V36: 3 | W36: 35 | X36: 65 | Y36: 1.28 | Z36: 2.64 | AA36: 110381 | AB36: 110382
A37: 11039 | B37: CA | C37: 威奇塔 | D37: U | E37: 46 | F37: 78 | G37: 0 | H37: 52 | I37: 93 | J37: 0 | K37: 98 | L37: 83 | M37: 62 | N37: 33 | O37: 2 | P37: 20 | Q37: 4 | R37: =SUM($S37:$V37) -> 6 | S37: 2 | T37: 2 | U37: 2 | V37: 0 | W37: 40 | X37: 70 | Y37: 1.28 | Z37: 2.4 | AA37: 110391
A38: 11040 | B38: CA | C38: 昆西 | D38: U | E38: 58 | F38: 73 | G38: 0 | H38: 56 | I38: 80 | J38: 0 | K38: 97 | L38: 83 | M38: 63 | N38: 32.7 | O38: 2 | P38: 12 | Q38: 4 | R38: =SUM($S38:$V38) -> 8 | S38: 2 | T38: 2 | U38: 2 | V38: 2 | W38: 40 | X38: 70 | Y38: 1.28 | Z38: 2.4 | AA38: 110401 | AB38: 110402
A39: 11043 | B39: CLT | C39: 北上 | D39: J | E39: 35 | F39: 36 | G39: 120 | H39: 33 | I39: 55 | J39: 2 | K39: 97 | L39: 78 | M39: 21 | N39: 36 | O39: 2 | P39: 20 | Q39: 3 | R39: =SUM($S39:$V39) -> 0 | S39: 0 | T39: 0 | U39: 0 | V39: 0 | W39: 25 | X39: 100 | Y39: 0.8 | Z39: 1.5 | AA39: 103771 | AB39: 110432
A40: 11044 | B40: CLT | C40: 大井 | D40: J | E40: 35 | F40: 36 | G40: 120 | H40: 33 | I40: 55 | J40: 2 | K40: 97 | L40: 78 | M40: 21 | N40: 36 | O40: 2 | P40: 10 | Q40: 3 | R40: =SUM($S40:$V40) -> 0 | S40: 0 | T40: 0 | U40: 0 | V40: 0 | W40: 25 | X40: 100 | Y40: 0.8 | Z40: 1.5 | AA40: 103771 | AB40: 110432
...

Sheet 装备数据-常规
A1: eid | B1: 种类 | C1: 名称 | D1: 种类-2 | E1: 耐久 | F1: 火力 | G1: 鱼雷 | H1: 装甲 | I1: 对潜 | J1: 索敌 | K1: 命中 | L1: 射程 | M1: 闪避 | N1: 幸运 | O1: 轰炸 | P1: 对空 | Q1: 对空倍率 | R1: 对空补正 | S1: 导弹突防 | T1: 导弹拦截 | U1: 铝耗 | V1: 特效 | W1: 特效-2 | X1: 特效数值 | Y1: 特效数值-2 | Z1: 描述 | AA1: 特效配置
A2: 10026 | B2: MainGun | C2: [战列主炮][超长][30火8空][限1]J国46厘米三连装炮 | D2: 主炮 | F2: 30 | L2: 4 | P2: 8 | Q2: 1 | R2: 0.25 | Z2: 对空补正25%
A3: 10035 | B3: MainGun | C3: [战列主炮][长程][24火2命]U国三联16英寸炮(MK6) | D3: 主炮 | F3: 24 | K3: 2 | L3: 3 | Q3: 1
A4: 10036 | B4: MainGun | C4: [战列主炮][超长][27火3命]U国三联16英寸炮(MK7) | D4: 主炮 | F4: 27 | K4: 3 | L4: 4 | Q4: 1
A5: 10049 | B5: AntiAirGun | C5: [防空]U国双联3英寸防空炮 | D5: 防空炮 | F5: 2 | K5: 2 | L5: 1 | P5: 12 | Q5: 3.1 | R5: 0.35 | Z5: 对空补正35%；对空倍率3.1
A6: 10068 | B6: Bomber | C6: [舰爆][10轰1空]BTD-1毁灭者 | D6: 轰炸机 | I6: 3 | O6: 10 | P6: 1 | Q6: 1 | U6: 5 | Z6: 铝耗5
A7: 10082 | B7: Radar | C7: [雷达][7索5命]改良型对海雷达 | D7: 雷达 | J7: 7 | K7: 5 | Q7: 1
A8: 10084 | B8: Sonar | C8: [声纳][10对潜]改良型声纳 | D8: 声纳 | I8: 10 | K8: 2 | Q8: 1
A9: 10094 | B9: Accessory | C9: [部件][闪避]改良型动力系统 | D9: 强化部件 | M9: 10 | Q9: 1
A10: 10095 | B10: Accessory | C10: [中船部件][装甲]附加装甲(中型) | D10: 强化部件 | H10: 7 | M10: -2 | Q10: 1
A11: 10096 | B11: Accessory | C11: [大船部件][装甲]附加装甲(大型) | D11: 强化部件 | H11: 9 | M11: -3 | Q11: 1
A12: 10102 | B12: MainGun | C12: [战列主炮][超长][25火1命]F国四联380毫米炮 | D12: 主炮 | F12: 25 | K12: 1 | L12: 4 | Q12: 1
A13: 10106 | B13: Radar | C13: [雷达][7索3命]先进型对空雷达 | D13: 雷达 | J13: 7 | K13: 3 | P13: 6 | Q13: 3.3 | R13: 0.4 | Z13: 对空补正40%；对空倍率3.3
A14: 10107 | B14: Radar | C14: [雷达][10索6命][限2]先进型对海雷达 | D14: 雷达 | J14: 10 | K14: 6 | M14: 3 | Q14: 1
A15: 10111 | B15: Sonar | C15: [声纳][12对潜][限1]先进型声纳 | D15: 声纳 | I15: 12 | K15: 3 | Q15: 1
A16: 10112 | B16: DepthMine | C16: [深投][10对潜]先进型深弹投射器 | D16: 深投 | I16: 10 | L16: 1 | Q16: 1
A17: 10113 | B17: DepthMine | C17: [深投][9对潜]捕鼠器深弹投射器 | D17: 深投 | I17: 9 | K17: 2 | L17: 1 | Q17: 1
A18: 10114 | B18: DepthMine | C18: [深投][15对潜]刺猬弹深弹投射器 | D18: 深投 | I18: 15 | K18: 5 | L18: 1 | Q18: 1
A19: 10115 | B19: Accessory | C19: [部件][装甲]附加装甲(小型) | D19: 强化部件 | H19: 5 | M19: -1 | Q19: 1
A20: 10116 | B20: Accessory | C20: [部件][闪避]先进型动力系统 | D20: 强化部件 | M20: 12 | Q20: 1
A21: 10117 | B21: Accessory | C21: [部件][闪避]发烟筒 | D21: 强化部件 | K21: -5 | M21: 15 | Q21: 1 | Z21: 重巡以下船只专用（航母类不能使用）
A22: 10127 | B22: Bomber | C22: [舰爆][20轰][高轰]B-25(杜立特队) | D22: 轰炸机 | O22: 20 | Q22: 1 | U22: 15 | Z22: 铝耗15
A23: 10129 | B23: Shell | C23: [炮弹][上限]超重弹 | D23: 炮弹 | F23: 5 | Q23: 1 | V23: 004 | W23: 4 | X23: 0.25 | Y23: {'num': 25} | Z23: 炮击战阶段增加25%攻击上限（同类弹药效果只会生效一个） | AA23: uplimit_buff:0.25
A24: 10130 | B24: Shell | C24: [炮弹][穿甲]91式穿甲弹 | D24: 炮弹 | F24: 6 | K24: 1 | Q24: 1 | V24: 003 | W24: 3 | X24: 0.2 | Y24: {'ap': 0.2} | Z24: 增加20%护甲穿透（同类弹药效果只生效一个） | AA24: pierce_coef:0.2
A25: 10140 | B25: DiveBomber | C25: [舰攻][16雷][限1]XTB2D空中海盗 | D25: 鱼雷机 | G25: 16 | I25: 3 | Q25: 1 | U25: 9 | Z25: 铝耗9
A26: 10145 | B26: Bomber | C26: [水爆][5轰2空]瑞云 | D26: 轰炸机 | I26: 2 | O26: 5 | P26: 2 | Q26: 1 | U26: 4 | Z26: 铝耗4
A27: 10146 | B27: Bomber | C27: [水爆][8轰]晴岚 | D27: 轰炸机 | O27: 8 | Q27: 1 | U27: 4 | Z27: 铝耗4
A28: 10147 | B28: MainGun | C28: [战列主炮][长程][26火]E国三联16英寸炮(改) | D28: 主炮 | F28: 26 | L28: 3 | Q28: 1
A29: 10151 | B29: Torpedo | C29: [鱼雷][12雷][限1]61厘米五连装氧气鱼雷 | D29: 鱼雷 | G29: 12 | K29: 1 | Q29: 1
A30: 10152 | B30: Torpedo | C30: [潜用鱼雷][15雷]53厘米氧气鱼雷(潜艇) | D30: 鱼雷 | G30: 15 | K30: 2 | Q30: 1
A31: 10153 | B31: Torpedo | C31: [潜用鱼雷][12雷]533毫米磁性鱼雷(潜艇) | D31: 鱼雷 | G31: 12 | K31: 4 | Q31: 1
A32: 10154 | B32: Torpedo | C32: [潜用鱼雷][12雷]21英寸鱼雷(潜艇) | D32: 鱼雷 | G32: 12 | K32: 1 | Q32: 1
A33: 10155 | B33: AntiAirGun | C33: [防空]E国博福斯40毫米防空机炮(六联) | D33: 防空炮 | F33: 3 | K33: 1 | L33: 1 | P33: 11 | Q33: 3.1 | R33: 0.35 | Z33: 对空补正35%；对空倍率3.1
A34: 10157 | B34: Radar | C34: [雷达][6索8命]E国274型雷达 | D34: 雷达 | J34: 6 | K34: 8 | Q34: 1
A35: 10169 | B35: Accessory | C35: [部件][装甲]普列塞水下防护系统 | D35: 强化部件 | H35: 8 | M35: 1 | Q35: 1
A36: 10170 | B36: Accessory | C36: [部件][降索敌]意式餐具套装 | D36: 强化部件 | J36: -3 | K36: 3 | N36: 3 | Q36: 1
A37: 10174 | B37: Torpedo | C37: [鱼雷][5雷3闪]F国旋转鱼雷发射器 | D37: 鱼雷 | G37: 5 | M37: 3 | Q37: 1
A38: 10177 | B38: MainGun | C38: [轻巡主炮][长程][8火]S国三联180毫米炮 | D38: 主炮 | F38: 8 | L38: 3 | Q38: 1
A39: 10191 | B39: MainGun | C39: [重巡主炮][中程][10火2命]U国三联8英寸炮(MK12/15) | D39: 主炮 | F39: 10 | K39: 2 | L39: 2 | Q39: 1
A40: 10213 | B40: Torpedo | C40: [潜用鱼雷][15雷]MK.16鱼雷（潜艇） | D40: 鱼雷 | G40: 15 | K40: 3 | Q40: 1
...

Sheet 舰船数据-深海
A1: cid | B1: 舰种 | C1: 名称 | D1: 国籍 | E1: 等级 | F1: 耐久 | G1: 火力 | H1: 鱼雷 | I1: 装甲 | J1: 对空 | K1: 对潜 | L1: 命中 | M1: 回避 | N1: 索敌 | O1: 航速 | P1: 射程 | Q1: 幸运 | R1: 装备1 | S1: 装备2 | T1: 装备3 | U1: 装备4 | V1: 总搭载 | W1: 搭载1 | X1: 搭载2 | Y1: 搭载3 | Z1: 搭载4 | AA1: 技能1 | AB1: 技能2 | AC1: 标签 | AD1: 备注
A2: 00000 | B2: BB | C2: 测试靶舰 | D2: Enemy | E2: 100 | F2: 9999 | G2: 0 | H2: 0 | I2: 180 | J2: 150 | K2: 0 | L2: 0 | M2: 100 | N2: 0 | O2: 27 | P2: 3 | Q2: 0 | R2: 对海雷达Ⅱ型 | V2: =SUM(W2:Z2) -> 0 | W2: 0 | X2: 0 | Y2: 0 | Z2: 0
A3: 00001 | B3: DD | C3: 驱逐Α级Ⅰ型 | D3: Enemy | E3: 1 | F3: 20 | G3: 5 | H3: 15 | I3: 5 | J3: 6 | K3: 25 | L3: 15 | M3: 14 | N3: 3 | O3: 35 | P3: 1 | Q3: 1 | R3: 小型单装炮 | V3: =SUM(W3:Z3) -> 0 | W3: 0 | X3: 0 | Y3: 0 | Z3: 0
A4: 00002 | B4: DD | C4: 驱逐Α级Ⅱ型 | D4: Enemy | E4: 17 | F4: 30 | G4: 15 | H4: 32 | I4: 12 | J4: 10 | K4: 35 | L4: 30 | M4: 30 | N4: 6 | O4: 40 | P4: 1 | Q4: 10 | R4: 小型单装炮 | S4: 大型鱼雷Ⅱ型 | V4: =SUM(W4:Z4) -> 0 | W4: 0 | X4: 0 | Y4: 0 | Z4: 0
A5: 00003 | B5: DD | C5: 驱逐Α级Ⅲ型 | D5: Enemy | E5: 53 | F5: 39 | G5: 32 | H5: 60 | I5: 24 | J5: 14 | K5: 82 | L5: 60 | M5: 60 | N5: 10 | O5: 45 | P5: 1 | Q5: 30 | R5: 对空雷达Ⅱ型 | S5: 深海声纳Ⅰ型 | T5: 深海深弹投射器Ⅰ型 | V5: =SUM(W5:Z5) -> 0 | W5: 0 | X5: 0 | Y5: 0 | Z5: 0
A6: 00004 | B6: DD | C6: 驱逐Α级Ⅳ型 | D6: Enemy | E6: 77 | F6: 44 | G6: 38 | H6: 77 | I6: 28 | J6: 18 | K6: 90 | L6: 80 | M6: 80 | N6: 12 | O6: 45 | P6: 1 | Q6: 50 | R6: 对空雷达Ⅲ型 | S6: 深海声纳Ⅱ型 | T6: 深海深弹投射器Ⅰ型 | V6: =SUM(W6:Z6) -> 0 | W6: 0 | X6: 0 | Y6: 0 | Z6: 0
A7: 00005 | B7: DD | C7: 驱逐Δ级Ⅰ型 | D7: Enemy | E7: 3 | F7: 28 | G7: 8 | H7: 24 | I7: 9 | J7: 8 | K7: 35 | L7: 18 | M7: 18 | N7: 4 | O7: 35 | P7: 1 | Q7: 5 | R7: 小型连装炮 | S7: 大型鱼雷Ⅰ型 | V7: =SUM(W7:Z7) -> 0 | W7: 0 | X7: 0 | Y7: 0 | Z7: 0
A8: 00006 | B8: DD | C8: 驱逐Δ级Ⅱ型 | D8: Enemy | E8: 29 | F8: 45 | G8: 20 | H8: 40 | I8: 18 | J8: 12 | K8: 45 | L8: 40 | M8: 40 | N8: 7 | O8: 40 | P8: 1 | Q8: 10 | R8: 小型连装炮 | S8: 大型鱼雷Ⅲ型 | V8: =SUM(W8:Z8) -> 0 | W8: 0 | X8: 0 | Y8: 0 | Z8: 0
A9: 00007 | B9: DD | C9: 驱逐Δ级Ⅲ型 | D9: Enemy | E9: 59 | F9: 50 | G9: 25 | H9: 60 | I9: 23 | J9: 16 | K9: 68 | L9: 65 | M9: 65 | N9: 10 | O9: 45 | P9: 1 | Q9: 30 | R9: 小型连装炮 | S9: 小型连装炮 | T9: 大型鱼雷Ⅲ型 | V9: =SUM(W9:Z9) -> 0 | W9: 0 | X9: 0 | Y9: 0 | Z9: 0
A10: 00008 | B10: DD | C10: 驱逐Γ级Ⅰ型 | D10: Enemy | E10: 1 | F10: 24 | G10: 6 | H10: 16 | I10: 7 | J10: 6 | K10: 30 | L10: 16 | M10: 16 | N10: 4 | O10: 35 | P10: 1 | Q10: 1 | R10: 小型连装炮 | S10: 大型鱼雷Ⅰ型 | V10: =SUM(W10:Z10) -> 0 | W10: 0 | X10: 0 | Y10: 0 | Z10: 0
A11: 00009 | B11: DD | C11: 驱逐Γ级Ⅱ型 | D11: Enemy | E11: 23 | F11: 40 | G11: 15 | H11: 32 | I11: 16 | J11: 10 | K11: 40 | L11: 35 | M11: 35 | N11: 7 | O11: 40 | P11: 1 | Q11: 10 | R11: 小型连装炮 | S11: 大型鱼雷Ⅲ型 | V11: =SUM(W11:Z11) -> 0 | W11: 0 | X11: 0 | Y11: 0 | Z11: 0
A12: 00010 | B12: DD | C12: 驱逐Γ级Ⅲ型 | D12: Enemy | E12: 46 | F12: 47 | G12: 30 | H12: 60 | I12: 27 | J12: 14 | K12: 60 | L12: 54 | M12: 54 | N12: 12 | O12: 45 | P12: 1 | Q12: 20 | R12: 小型连装炮 | S12: 大型鱼雷Ⅲ型 | T12: 深海深弹投射器Ⅰ型 | V12: =SUM(W12:Z12) -> 0 | W12: 0 | X12: 0 | Y12: 0 | Z12: 0
A13: 00011 | B13: DD | C13: 驱逐Γ级Ⅳ型 | D13: Enemy | E13: 65 | F13: 53 | G13: 42 | H13: 80 | I13: 33 | J13: 20 | K13: 80 | L13: 70 | M13: 70 | N13: 15 | O13: 45 | P13: 1 | Q13: 30 | R13: 小型连装炮 | S13: 大型鱼雷Ⅲ型 | T13: 深海深弹投射器Ⅰ型 | V13: =SUM(W13:Z13) -> 0 | W13: 0 | X13: 0 | Y13: 0 | Z13: 0
A14: 00012 | B14: DD | C14: 驱逐Β级Ⅰ型 | D14: Enemy | E14: 1 | F14: 22 | G14: 7 | H14: 16 | I14: 6 | J14: 7 | K14: 25 | L14: 15 | M14: 15 | N14: 3 | O14: 35 | P14: 1 | Q14: 1 | R14: 小型连装炮 | V14: =SUM(W14:Z14) -> 0 | W14: 0 | X14: 0 | Y14: 0 | Z14: 0
A15: 00013 | B15: DD | C15: 驱逐Β级Ⅱ型 | D15: Enemy | E15: 17 | F15: 35 | G15: 20 | H15: 32 | I15: 14 | J15: 12 | K15: 35 | L15: 30 | M15: 30 | N15: 6 | O15: 40 | P15: 1 | Q15: 10 | R15: 小型连装炮 | S15: 大型鱼雷Ⅱ型 | V15: =SUM(W15:Z15) -> 0 | W15: 0 | X15: 0 | Y15: 0 | Z15: 0
A16: 00014 | B16: DD | C16: 驱逐Β级Ⅲ型 | D16: Enemy | E16: 44 | F16: 43 | G16: 33 | H16: 60 | I16: 24 | J16: 15 | K16: 55 | L16: 52 | M16: 52 | N16: 10 | O16: 45 | P16: 1 | Q16: 20 | R16: 小型连装炮 | S16: 大型鱼雷Ⅲ型 | T16: 深海深弹投射器Ⅰ型 | V16: =SUM(W16:Z16) -> 0 | W16: 0 | X16: 0 | Y16: 0 | Z16: 0
A17: 00015 | B17: DD | C17: 驱逐Β级Ⅳ型 | D17: Enemy | E17: 67 | F17: 51 | G17: 42 | H17: 80 | I17: 30 | J17: 20 | K17: 78 | L17: 72 | M17: 72 | N17: 12 | O17: 45 | P17: 1 | Q17: 30 | R17: 小型连装炮 | S17: 大型鱼雷Ⅲ型 | T17: 深海深弹投射器Ⅰ型 | V17: =SUM(W17:Z17) -> 0 | W17: 0 | X17: 0 | Y17: 0 | Z17: 0
A18: 00016 | B18: CV | C18: 航母Ο级Ⅰ型 | D18: Enemy | E18: 3 | F18: 85 | G18: 10 | H18: 0 | I18: 40 | J18: 30 | K18: 0 | L18: 18 | M18: 3 | N18: 40 | O18: 25 | P18: 1 | Q18: 1 | R18: 深海战斗机Ⅰ型 | S18: 深海轰炸机Ⅰ型 | T18: 深海鱼雷机Ⅰ型 | V18: =SUM(W18:Z18) -> 81 | W18: 27 | X18: 27 | Y18: 27 | Z18: 0
A19: 00017 | B19: CV | C19: 航母Ο级Ⅱ型 | D19: Enemy | E19: 22 | F19: 88 | G19: 20 | H19: 0 | I19: 55 | J19: 40 | K19: 0 | L19: 34 | M19: 12 | N19: 50 | O19: 30 | P19: 1 | Q19: 10 | R19: 深海战斗机Ⅱ型 | S19: 深海鱼雷机Ⅱ型 | T19: 深海轰炸机Ⅱ型 | V19: =SUM(W19:Z19) -> 90 | W19: 30 | X19: 30 | Y19: 30 | Z19: 0
A20: 00018 | B20: CV | C20: 航母Ο级Ⅲ型 | D20: Enemy | E20: 47 | F20: 96 | G20: 35 | H20: 0 | I20: 80 | J20: 50 | K20: 0 | L20: 55 | M20: 45 | N20: 50 | O20: 35 | P20: 1 | Q20: 20 | R20: 深海战斗机Ⅱ型 | S20: 深海鱼雷机Ⅱ型 | T20: 深海轰炸机Ⅱ型 | V20: =SUM(W20:Z20) -> 96 | W20: 32 | X20: 32 | Y20: 32 | Z20: 0
A21: 00019 | B21: CV | C21: 航母Ο级Ⅳ型 | D21: Enemy | E21: 71 | F21: 160 | G21: 50 | H21: 0 | I21: 120 | J21: 70 | K21: 0 | L21: 75 | M21: 50 | N21: 60 | O21: 35 | P21: 1 | Q21: 30 | R21: 深海战斗机Ⅲ型 | S21: 深海轰炸机Ⅱ型 | T21: 深海鱼雷机Ⅱ型 | V21: =SUM(W21:Z21) -> 144 | W21: 36 | X21: 36 | Y21: 36 | Z21: 36
A22: 00020 | B22: CL | C22: 轻巡Η级Ⅰ型 | D22: Enemy | E22: 1 | F22: 39 | G22: 24 | H22: 28 | I22: 20 | J22: 12 | K22: 50 | L22: 15 | M22: 15 | N22: 6 | O22: 30 | P22: 2 | Q22: 5 | R22: 中型连装炮 | S22: 大型鱼雷Ⅰ型 | T22: 深海侦察机 | V22: =SUM(W22:Z22) -> 6 | W22: 2 | X22: 2 | Y22: 2 | Z22: 0
A23: 00021 | B23: CL | C23: 轻巡Η级Ⅱ型 | D23: Enemy | E23: 21 | F23: 55 | G23: 36 | H23: 48 | I23: 36 | J23: 18 | K23: 50 | L23: 33 | M23: 28 | N23: 6 | O23: 33 | P23: 2 | Q23: 10 | R23: 中型连装炮 | S23: 大型鱼雷Ⅰ型 | T23: 深海侦察机 | V23: =SUM(W23:Z23) -> 6 | W23: 2 | X23: 2 | Y23: 2 | Z23: 0
A24: 00022 | B24: CL | C24: 轻巡Η级Ⅲ型 | D24: Enemy | E24: 41 | F24: 56 | G24: 42 | H24: 65 | I24: 39 | J24: 24 | K24: 50 | L24: 50 | M24: 47 | N24: 6 | O24: 36 | P24: 2 | Q24: 20 | R24: 中型连装炮 | S24: 大型鱼雷Ⅰ型 | T24: 深海侦察机 | V24: =SUM(W24:Z24) -> 6 | W24: 2 | X24: 2 | Y24: 2 | Z24: 0
A25: 00023 | B25: CL | C25: 轻巡Ζ级Ⅰ型 | D25: Enemy | E25: 1 | F25: 36 | G25: 16 | H25: 28 | I25: 18 | J25: 12 | K25: 40 | L25: 15 | M25: 15 | N25: 6 | O25: 30 | P25: 2 | Q25: 1 | R25: 中型连装炮 | S25: 深海侦察机 | V25: =SUM(W25:Z25) -> 2 | W25: 1 | X25: 1 | Y25: 0 | Z25: 0
A26: 00024 | B26: CL | C26: 轻巡Ζ级Ⅱ型 | D26: Enemy | E26: 17 | F26: 52 | G26: 34 | H26: 48 | I26: 32 | J26: 13 | K26: 45 | L26: 30 | M26: 26 | N26: 6 | O26: 33 | P26: 2 | Q26: 10 | R26: 中型连装炮 | S26: 深海侦察机 | V26: =SUM(W26:Z26) -> 2 | W26: 1 | X26: 1 | Y26: 0 | Z26: 0
A27: 00025 | B27: CL | C27: 轻巡Ζ级Ⅲ型 | D27: Enemy | E27: 47 | F27: 57 | G27: 48 | H27: 80 | I27: 39 | J27: 20 | K27: 80 | L27: 55 | M27: 46 | N27: 24 | O27: 36 | P27: 2 | Q27: 20 | R27: 中型连装炮 | S27: 深海侦察机 | T27: 深海深弹投射器Ⅰ型 | U27: 深海声纳Ⅰ型 | V27: =SUM(W27:Z27) -> 8 | W27: 2 | X27: 2 | Y27: 2 | Z27: 2
A28: 00026 | B28: CL | C28: 轻巡Ζ级Ⅳ型 | D28: Enemy | E28: 65 | F28: 62 | G28: 54 | H28: 90 | I28: 43 | J28: 27 | K28: 80 | L28: 70 | M28: 63 | N28: 40 | O28: 36 | P28: 2 | Q28: 30 | R28: 中型连装炮 | S28: 深海侦察机 | T28: 深海深弹投射器Ⅰ型 | U28: 深海声纳Ⅰ型 | V28: =SUM(W28:Z28) -> 8 | W28: 2 | X28: 2 | Y28: 2 | Z28: 2
A29: 00027 | B29: CL | C29: 轻巡Ε级Ⅰ型 | D29: Enemy | E29: 2 | F29: 33 | G29: 14 | H29: 24 | I29: 15 | J29: 10 | K29: 30 | L29: 17 | M29: 15 | N29: 6 | O29: 30 | P29: 2 | Q29: 1 | R29: 小型连装高射炮 | S29: 深海侦察机 | V29: =SUM(W29:Z29) -> 2 | W29: 1 | X29: 1 | Y29: 0 | Z29: 0
A30: 00028 | B30: CL | C30: 轻巡Ε级Ⅱ型 | D30: Enemy | E30: 16 | F30: 48 | G30: 30 | H30: 40 | I30: 30 | J30: 20 | K30: 40 | L30: 29 | M30: 24 | N30: 6 | O30: 33 | P30: 2 | Q30: 10 | R30: 小型连装高射炮 | S30: 深海侦察机 | V30: =SUM(W30:Z30) -> 2 | W30: 1 | X30: 1 | Y30: 0 | Z30: 0
A31: 00029 | B31: CL | C31: 轻巡Ε级Ⅲ型 | D31: Enemy | E31: 33 | F31: 53 | G31: 42 | H31: 72 | I31: 36 | J31: 27 | K31: 70 | L31: 43 | M31: 44 | N31: 20 | O31: 36 | P31: 2 | Q31: 20 | R31: 小型连装高射炮 | S31: 深海深弹投射器Ⅰ型 | T31: 深海声纳Ⅰ型 | V31: =SUM(W31:Z31) -> 8 | W31: 2 | X31: 2 | Y31: 2 | Z31: 2
A32: 00030 | B32: CL | C32: 轻巡Ε级Ⅳ型 | D32: Enemy | E32: 73 | F32: 59 | G32: 54 | H32: 90 | I32: 42 | J32: 34 | K32: 90 | L32: 77 | M32: 64 | N32: 34 | O32: 36 | P32: 2 | Q32: 30 | R32: 小型连装高射炮 | S32: 深海深弹投射器Ⅰ型 | T32: 深海声纳Ⅰ型 | U32: 大型鱼雷Ⅲ型 | V32: =SUM(W32:Z32) -> 8 | W32: 2 | X32: 2 | Y32: 2 | Z32: 2
A33: 00031 | B33: CVL | C33: 轻母Ξ级Ⅰ型 | D33: Enemy | E33: 4 | F33: 65 | G33: 5 | H33: 0 | I33: 25 | J33: 15 | K33: 0 | L33: 19 | M33: 3 | N33: 30 | O33: 25 | P33: 1 | Q33: 1 | R33: 深海战斗机Ⅰ型 | S33: 深海轰炸机Ⅰ型 | T33: 深海鱼雷机Ⅰ型 | V33: =SUM(W33:Z33) -> 54 | W33: 18 | X33: 18 | Y33: 18 | Z33: 0
A34: 00032 | B34: CVL | C34: 轻母Ξ级Ⅱ型 | D34: Enemy | E34: 23 | F34: 70 | G34: 10 | H34: 0 | I34: 35 | J34: 15 | K34: 0 | L34: 35 | M34: 10 | N34: 30 | O34: 30 | P34: 1 | Q34: 10 | R34: 深海战斗机Ⅱ型 | S34: 深海轰炸机Ⅰ型 | T34: 深海鱼雷机Ⅰ型 | V34: =SUM(W34:Z34) -> 72 | W34: 24 | X34: 24 | Y34: 24 | Z34: 0
A35: 00033 | B35: CVL | C35: 轻母Ξ级Ⅲ型 | D35: Enemy | E35: 41 | F35: 84 | G35: 25 | H35: 0 | I35: 70 | J35: 36 | K35: 0 | L35: 50 | M35: 40 | N35: 40 | O35: 35 | P35: 1 | Q35: 30 | R35: 深海战斗机Ⅱ型 | S35: 深海轰炸机Ⅱ型 | T35: 深海轰炸机Ⅱ型 | U35: 深海鱼雷机Ⅱ型 | V35: =SUM(W35:Z35) -> 88 | W35: 22 | X35: 22 | Y35: 22 | Z35: 22
A36: 00034 | B36: CVL | C36: 轻母Ξ级Ⅳ型 | D36: Enemy | E36: 64 | F36: 88 | G36: 35 | H36: 0 | I36: 75 | J36: 44 | K36: 0 | L36: 69 | M36: 60 | N36: 50 | O36: 40 | P36: 1 | Q36: 50 | R36: 深海战斗机Ⅲ型 | S36: 深海轰炸机Ⅱ型 | T36: 深海轰炸机Ⅱ型 | U36: 深海鱼雷机Ⅱ型 | V36: =SUM(W36:Z36) -> 108 | W36: 27 | X36: 27 | Y36: 27 | Z36: 27
A37: 00035 | B37: CA | C37: 重巡Ι级Ⅰ型 | D37: Enemy | E37: 3 | F37: 58 | G37: 32 | H37: 32 | I37: 28 | J37: 16 | K37: 0 | L37: 18 | M37: 12 | N37: 10 | O37: 25 | P37: 2 | Q37: 1 | R37: 中型单装炮 | S37: 大型鱼雷Ⅰ型 | T37: 深海侦察机 | V37: =SUM(W37:Z37) -> 9 | W37: 3 | X37: 3 | Y37: 3 | Z37: 0
A38: 00036 | B38: CA | C38: 重巡Ι级Ⅱ型 | D38: Enemy | E38: 21 | F38: 60 | G38: 58 | H38: 42 | I38: 60 | J38: 20 | K38: 0 | L38: 33 | M38: 20 | N38: 15 | O38: 30 | P38: 2 | Q38: 10 | R38: 中型单装炮 | S38: 中型连装炮 | T38: 深海侦察机 | U38: 深海侦察机 | V38: =SUM(W38:Z38) -> 12 | W38: 3 | X38: 3 | Y38: 3 | Z38: 3
A39: 00037 | B39: CA | C39: 重巡Ι级Ⅲ型 | D39: Enemy | E39: 51 | F39: 76 | G39: 68 | H39: 48 | I39: 70 | J39: 30 | K39: 0 | L39: 58 | M39: 50 | N39: 20 | O39: 35 | P39: 2 | Q39: 20 | R39: 中型单装炮 | S39: 中型连装炮 | T39: 大型鱼雷Ⅲ型 | U39: 深海侦察机 | V39: =SUM(W39:Z39) -> 16 | W39: 4 | X39: 4 | Y39: 4 | Z39: 4
A40: 00038 | B40: CA | C40: 重巡Ι级Ⅳ型 | D40: Enemy | E40: 84 | F40: 88 | G40: 88 | H40: 80 | I40: 80 | J40: 40 | K40: 0 | L40: 86 | M40: 57 | N40: 30 | O40: 35 | P40: 2 | Q40: 40 | R40: 中型单装炮 | S40: 中型单装炮 | T40: 大型鱼雷Ⅲ型 | U40: 深海高速侦察机 | V40: =SUM(W40:Z40) -> 16 | W40: 4 | X40: 4 | Y40: 4 | Z40: 4
...

Sheet 装备数据-深海
A1: eid | B1: 种类 | C1: 名称 | D1: 种类-2 | E1: 耐久 | F1: 火力 | G1: 鱼雷 | H1: 装甲 | I1: 对潜 | J1: 索敌 | K1: 命中 | L1: 射程 | M1: 闪避 | N1: 幸运 | O1: 轰炸 | P1: 对空 | Q1: 对空倍率 | R1: 对空补正 | S1: 导弹突防 | T1: 导弹拦截 | U1: 铝耗 | V1: 特效 | W1: 特效数值 | X1: 特效配置
A2: 00001 | B2: MainGun | C2: 小型单装炮 | D2: 主炮 | F2: 1 | L2: 1 | Q2: 2
A3: 00002 | B3: MainGun | C3: 小型连装炮 | D3: 主炮 | F3: 2 | L3: 1 | Q3: 2
A4: 00003 | B4: MainGun | C4: 小型单装高射炮 | D4: 主炮 | F4: 1 | L4: 1 | P4: 1 | Q4: 2
A5: 00004 | B5: MainGun | C5: 小型连装高射炮 | D5: 主炮 | F5: 2 | L5: 2 | P5: 2 | Q5: 2
A6: 00005 | B6: MainGun | C6: 中型单装炮 | D6: 主炮 | F6: 8 | L6: 2 | P6: 2 | Q6: 2
A7: 00006 | B7: MainGun | C7: 中型连装炮 | D7: 主炮 | F7: 3 | L7: 2 | P7: 3 | Q7: 2
A8: 00007 | B8: MainGun | C8: 大型单装炮 | D8: 主炮 | F8: 10 | L8: 3 | P8: 4 | Q8: 2 | R8: 0.2
A9: 00008 | B9: MainGun | C9: 大型连装炮 | D9: 主炮 | F9: 15 | L9: 3 | P9: 4 | Q9: 2 | R9: 0.2
A10: 00009 | B10: MainGun | C10: 大型三连装炮 | D10: 主炮 | F10: 20 | L10: 3 | P10: 5 | Q10: 2 | R10: 0.2
A11: 00010 | B11: SecondaryGun | C11: 小型副炮 | D11: 副炮 | F11: 1 | L11: 1 | P11: 2 | Q11: 2
A12: 00011 | B12: SecondaryGun | C12: 中型副炮 | D12: 副炮 | F12: 1 | L12: 2 | Q12: 2
A13: 00012 | B13: SecondaryGun | C13: 大型副炮 | D13: 副炮 | F13: 7 | L13: 2 | P13: 3 | Q13: 2
A14: 00013 | B14: Torpedo | C14: 大型鱼雷Ⅰ型 | D14: 鱼雷 | G14: 2 | L14: 1 | Q14: 2
A15: 00014 | B15: Torpedo | C15: 大型鱼雷Ⅱ型 | D15: 鱼雷 | G15: 5 | L15: 1 | Q15: 2
A16: 00015 | B16: Torpedo | C16: 大型鱼雷Ⅲ型 | D16: 鱼雷 | G16: 10 | L16: 1 | Q16: 2
A17: 00016 | B17: DiveBomber | C17: 深海鱼雷机Ⅰ型 | D17: 鱼雷机 | G17: 4 | I17: 2 | J17: 5 | Q17: 2
A18: 00017 | B18: DiveBomber | C18: 深海鱼雷机Ⅱ型 | D18: 鱼雷机 | G18: 6 | I18: 4 | J18: 5 | Q18: 2
A19: 00018 | B19: DiveBomber | C19: 深海鱼雷机Ⅲ型 | D19: 鱼雷机 | G19: 11 | I19: 7 | J19: 5 | P19: 4 | Q19: 2
A20: 00019 | B20: Fighter | C20: 深海战斗机Ⅰ型 | D20: 战斗机 | P20: 2 | Q20: 2
A21: 00020 | B21: Fighter | C21: 深海战斗机Ⅱ型 | D21: 战斗机 | P21: 5 | Q21: 2
A22: 00021 | B22: Fighter | C22: 深海战斗机Ⅲ型 | D22: 战斗机 | P22: 9 | Q22: 2
A23: 00022 | B23: Fighter | C23: 深海高速战斗机 | D23: 战斗机 | P23: 13 | Q23: 2
A24: 00023 | B24: Bomber | C24: 深海轰炸机Ⅰ型 | D24: 轰炸机 | I24: 1 | O24: 3 | Q24: 2
A25: 00024 | B25: Bomber | C25: 深海轰炸机Ⅱ型 | D25: 轰炸机 | I25: 2 | O25: 6 | Q25: 2
A26: 00025 | B26: ScoutPlane | C26: 深海侦察机 | D26: 侦察机 | I26: 1 | J26: 5 | O26: 1 | P26: 1 | Q26: 2
A27: 00026 | B27: ScoutPlane | C27: 深海高速侦察机 | D27: 侦察机 | I27: 2 | J27: 10 | O27: 4 | P27: 2 | Q27: 2
A28: 00027 | B28: Radar | C28: 对空雷达Ⅰ型 | D28: 雷达 | J28: 5 | K28: 5 | P28: 5 | Q28: 2 | R28: 0.5
A29: 00028 | B29: Radar | C29: 对海雷达Ⅰ型 | D29: 雷达 | J29: 5 | K29: 10 | Q29: 2 | R29: 0.2
A30: 00029 | B30: Radar | C30: 对空雷达Ⅱ型 | D30: 雷达 | J30: 10 | K30: 15 | Q30: 2 | R30: 0.5
A31: 00030 | B31: Radar | C31: 对海雷达Ⅱ型 | D31: 雷达 | J31: 10 | K31: 5 | P31: 10 | Q31: 2 | R31: 0.2
A32: 00031 | B32: Radar | C32: 对空雷达Ⅲ型 | D32: 雷达 | I32: 5 | J32: 16 | K32: 24 | M32: 3 | P32: 5 | Q32: 2 | R32: 0.5
A33: 00032 | B33: Radar | C33: 对海雷达Ⅲ型 | D33: 雷达 | I33: 5 | J33: 12 | K33: 16 | M33: 2 | P33: 18 | Q33: 2 | R33: 0.2
A34: 00033 | B34: Accessory | C34: 深海动力系统Ⅰ型 | D34: 强化部件 | M34: 10 | Q34: 2
A35: 00034 | B35: Accessory | C35: 深海动力系统Ⅱ型 | D35: 强化部件 | M35: 15 | Q35: 2
A36: 00035 | B36: Shell | C36: 延时引信防空炮弹 | D36: 炮弹 | P36: 10 | Q36: 2
A37: 00036 | B37: Shell | C37: 深海特制穿甲弹 | D37: 炮弹 | F37: 15 | K37: 5 | Q37: 2
A38: 00037 | B38: AntiAirGun | C38: 小型防空机枪 | D38: 防空炮 | P38: 2 | Q38: 2 | R38: 0.4
A39: 00038 | B39: AntiAirGun | C39: 中型防空机枪 | D39: 防空炮 | P39: 4 | Q39: 2 | R39: 0.4
A40: 00039 | B40: AntiAirGun | C40: 大型防空机枪 | D40: 防空炮 | P40: 8 | Q40: 2 | R40: 0.4
...

Sheet 海图
A1: pid | B1: 名称 | C1: 种类 | D1: 点位等级 | E1: 迂回 | F1: 阵容1 | M1: 备注1 | S1: 阵容2 | Z1: 备注2 | AF1: 阵容3 | AM1: 备注3
A2: 00000 | B2: α | C2: Entrance | D2: 0 | E2: 0 | M2: =IFERROR(VLOOKUP(G2,'舰船数据-深海'!$A:$C,3,FALSE),) -> 0 | N2: =IFERROR(VLOOKUP(H2,'舰船数据-深海'!$A:$C,3,FALSE),) -> 0 | O2: =IFERROR(VLOOKUP(I2,'舰船数据-深海'!$A:$C,3,FALSE),) -> 0 | P2: =IFERROR(VLOOKUP(J2,'舰船数据-深海'!$A:$C,3,FALSE),) -> 0 | Q2: =IFERROR(VLOOKUP(K2,'舰船数据-深海'!$A:$C,3,FALSE),) -> 0 | R2: =IFERROR(VLOOKUP(L2,'舰船数据-深海'!$A:$C,3,FALSE),) -> 0 | Z2: =IFERROR(VLOOKUP(T2,'舰船数据-深海'!$A:$C,3,FALSE),) -> 0 | AA2: =IFERROR(VLOOKUP(U2,'舰船数据-深海'!$A:$C,3,FALSE),) -> 0 | AB2: =IFERROR(VLOOKUP(V2,'舰船数据-深海'!$A:$C,3,FALSE),) -> 0 | AC2: =IFERROR(VLOOKUP(W2,'舰船数据-深海'!$A:$C,3,FALSE),) -> 0 | AD2: =IFERROR(VLOOKUP(X2,'舰船数据-深海'!$A:$C,3,FALSE),) -> 0 | AE2: =IFERROR(VLOOKUP(Y2,'舰船数据-深海'!$A:$C,3,FALSE),) -> 0 | AM2: =IFERROR(VLOOKUP(AG2,'舰船数据-深海'!$A:$C,3,FALSE),) -> 0 | AN2: =IFERROR(VLOOKUP(AH2,'舰船数据-深海'!$A:$C,3,FALSE),) -> 0 | AO2: =IFERROR(VLOOKUP(AI2,'舰船数据-深海'!$A:$C,3,FALSE),) -> 0 | AP2: =IFERROR(VLOOKUP(AJ2,'舰船数据-深海'!$A:$C,3,FALSE),) -> 0 | AQ2: =IFERROR(VLOOKUP(AK2,'舰船数据-深海'!$A:$C,3,FALSE),) -> 0 | AR2: =IFERROR(VLOOKUP(AL2,'舰船数据-深海'!$A:$C,3,FALSE),) -> 0
A3: 00001 | B3: B | C3: NormalBattle | D3: 1 | E3: 0 | F3: 1 | G3: 00067 | H3: 00067 | I3: 00090 | J3: 00090 | K3: 00093 | L3: 00093 | M3: =IFERROR(VLOOKUP(G3,'舰船数据-深海'!$A:$C,3,FALSE),) -> 战巡Κ级Ⅲ型 | N3: =IFERROR(VLOOKUP(H3,'舰船数据-深海'!$A:$C,3,FALSE),) -> 战巡Κ级Ⅲ型 | O3: =IFERROR(VLOOKUP(I3,'舰船数据-深海'!$A:$C,3,FALSE),) -> 重巡Ω级Ⅱ型 | P3: =IFERROR(VLOOKUP(J3,'舰船数据-深海'!$A:$C,3,FALSE),) -> 重巡Ω级Ⅱ型 | Q3: =IFERROR(VLOOKUP(K3,'舰船数据-深海'!$A:$C,3,FALSE),) -> 轻巡ei级Ⅰ型 | R3: =IFERROR(VLOOKUP(L3,'舰船数据-深海'!$A:$C,3,FALSE),) -> 轻巡ei级Ⅰ型 | Z3: =IFERROR(VLOOKUP(T3,'舰船数据-深海'!$A:$C,3,FALSE),) -> 0 | AA3: =IFERROR(VLOOKUP(U3,'舰船数据-深海'!$A:$C,3,FALSE),) -> 0 | AB3: =IFERROR(VLOOKUP(V3,'舰船数据-深海'!$A:$C,3,FALSE),) -> 0 | AC3: =IFERROR(VLOOKUP(W3,'舰船数据-深海'!$A:$C,3,FALSE),) -> 0 | AD3: =IFERROR(VLOOKUP(X3,'舰船数据-深海'!$A:$C,3,FALSE),) -> 0 | AE3: =IFERROR(VLOOKUP(Y3,'舰船数据-深海'!$A:$C,3,FALSE),) -> 0 | AM3: =IFERROR(VLOOKUP(AG3,'舰船数据-深海'!$A:$C,3,FALSE),) -> 0 | AN3: =IFERROR(VLOOKUP(AH3,'舰船数据-深海'!$A:$C,3,FALSE),) -> 0 | AO3: =IFERROR(VLOOKUP(AI3,'舰船数据-深海'!$A:$C,3,FALSE),) -> 0 | AP3: =IFERROR(VLOOKUP(AJ3,'舰船数据-深海'!$A:$C,3,FALSE),) -> 0 | AQ3: =IFERROR(VLOOKUP(AK3,'舰船数据-深海'!$A:$C,3,FALSE),) -> 0 | AR3: =IFERROR(VLOOKUP(AL3,'舰船数据-深海'!$A:$C,3,FALSE),) -> 0
A4: 00002 | B4: F | C4: NormalBattle | D4: 2 | E4: 0 | F4: 1 | G4: 00207 | H4: 00087 | I4: 00019 | J4: 00033 | K4: 00095 | L4: 00094 | M4: =IFERROR(VLOOKUP(G4,'舰船数据-深海'!$A:$C,3,FALSE),) -> 大巡ce级Ⅳ型 | N4: =IFERROR(VLOOKUP(H4,'舰船数据-深海'!$A:$C,3,FALSE),) -> 战列Ψ级Ⅲ型 | O4: =IFERROR(VLOOKUP(I4,'舰船数据-深海'!$A:$C,3,FALSE),) -> 航母Ο级Ⅳ型 | P4: =IFERROR(VLOOKUP(J4,'舰船数据-深海'!$A:$C,3,FALSE),) -> 轻母Ξ级Ⅲ型 | Q4: =IFERROR(VLOOKUP(K4,'舰船数据-深海'!$A:$C,3,FALSE),) -> 轻巡ei级Ⅲ型 | R4: =IFERROR(VLOOKUP(L4,'舰船数据-深海'!$A:$C,3,FALSE),) -> 轻巡ei级Ⅱ型 | Z4: =IFERROR(VLOOKUP(T4,'舰船数据-深海'!$A:$C,3,FALSE),) -> 0 | AA4: =IFERROR(VLOOKUP(U4,'舰船数据-深海'!$A:$C,3,FALSE),) -> 0 | AB4: =IFERROR(VLOOKUP(V4,'舰船数据-深海'!$A:$C,3,FALSE),) -> 0 | AC4: =IFERROR(VLOOKUP(W4,'舰船数据-深海'!$A:$C,3,FALSE),) -> 0 | AD4: =IFERROR(VLOOKUP(X4,'舰船数据-深海'!$A:$C,3,FALSE),) -> 0 | AE4: =IFERROR(VLOOKUP(Y4,'舰船数据-深海'!$A:$C,3,FALSE),) -> 0 | AM4: =IFERROR(VLOOKUP(AG4,'舰船数据-深海'!$A:$C,3,FALSE),) -> 0 | AN4: =IFERROR(VLOOKUP(AH4,'舰船数据-深海'!$A:$C,3,FALSE),) -> 0 | AO4: =IFERROR(VLOOKUP(AI4,'舰船数据-深海'!$A:$C,3,FALSE),) -> 0 | AP4: =IFERROR(VLOOKUP(AJ4,'舰船数据-深海'!$A:$C,3,FALSE),) -> 0 | AQ4: =IFERROR(VLOOKUP(AK4,'舰船数据-深海'!$A:$C,3,FALSE),) -> 0 | AR4: =IFERROR(VLOOKUP(AL4,'舰船数据-深海'!$A:$C,3,FALSE),) -> 0
A5: 00003 | B5: I | C5: NormalBattle | D5: 3 | E5: 0 | F5: 1 | G5: 00088 | H5: 00088 | I5: 00019 | J5: 00019 | K5: 00075 | M5: =IFERROR(VLOOKUP(G5,'舰船数据-深海'!$A:$C,3,FALSE),) -> 战列Ψ级Ⅳ型 | N5: =IFERROR(VLOOKUP(H5,'舰船数据-深海'!$A:$C,3,FALSE),) -> 战列Ψ级Ⅳ型 | O5: =IFERROR(VLOOKUP(I5,'舰船数据-深海'!$A:$C,3,FALSE),) -> 航母Ο级Ⅳ型 | P5: =IFERROR(VLOOKUP(J5,'舰船数据-深海'!$A:$C,3,FALSE),) -> 航母Ο级Ⅳ型 | Q5: =IFERROR(VLOOKUP(K5,'舰船数据-深海'!$A:$C,3,FALSE),) -> 驱逐Τ级Ⅲ型 | R5: =IFERROR(VLOOKUP(L5,'舰船数据-深海'!$A:$C,3,FALSE),) -> 0 | Z5: =IFERROR(VLOOKUP(T5,'舰船数据-深海'!$A:$C,3,FALSE),) -> 0 | AA5: =IFERROR(VLOOKUP(U5,'舰船数据-深海'!$A:$C,3,FALSE),) -> 0 | AB5: =IFERROR(VLOOKUP(V5,'舰船数据-深海'!$A:$C,3,FALSE),) -> 0 | AC5: =IFERROR(VLOOKUP(W5,'舰船数据-深海'!$A:$C,3,FALSE),) -> 0 | AD5: =IFERROR(VLOOKUP(X5,'舰船数据-深海'!$A:$C,3,FALSE),) -> 0 | AE5: =IFERROR(VLOOKUP(Y5,'舰船数据-深海'!$A:$C,3,FALSE),) -> 0 | AM5: =IFERROR(VLOOKUP(AG5,'舰船数据-深海'!$A:$C,3,FALSE),) -> 0 | AN5: =IFERROR(VLOOKUP(AH5,'舰船数据-深海'!$A:$C,3,FALSE),) -> 0 | AO5: =IFERROR(VLOOKUP(AI5,'舰船数据-深海'!$A:$C,3,FALSE),) -> 0 | AP5: =IFERROR(VLOOKUP(AJ5,'舰船数据-深海'!$A:$C,3,FALSE),) -> 0 | AQ5: =IFERROR(VLOOKUP(AK5,'舰船数据-深海'!$A:$C,3,FALSE),) -> 0 | AR5: =IFERROR(VLOOKUP(AL5,'舰船数据-深海'!$A:$C,3,FALSE),) -> 0
A6: 00004 | B6: N | C6: NormalBattle | D6: 5 | E6: 0 | F6: 1 | G6: 01031 | H6: 01032 | I6: 01033 | J6: 01034 | K6: 01035 | L6: 01036 | M6: =IFERROR(VLOOKUP(G6,'舰船数据-深海'!$A:$C,3,FALSE),) -> Taiho | N6: =IFERROR(VLOOKUP(H6,'舰船数据-深海'!$A:$C,3,FALSE),) -> X. Fliegerkorps | O6: =IFERROR(VLOOKUP(I6,'舰船数据-深海'!$A:$C,3,FALSE),) -> Cyou-yamato | P6: =IFERROR(VLOOKUP(J6,'舰船数据-深海'!$A:$C,3,FALSE),) -> Musashi | Q6: =IFERROR(VLOOKUP(K6,'舰船数据-深海'!$A:$C,3,FALSE),) -> Zumwalt | R6: =IFERROR(VLOOKUP(L6,'舰船数据-深海'!$A:$C,3,FALSE),) -> SouthDakota | Z6: =IFERROR(VLOOKUP(T6,'舰船数据-深海'!$A:$C,3,FALSE),) -> 0 | AA6: =IFERROR(VLOOKUP(U6,'舰船数据-深海'!$A:$C,3,FALSE),) -> 0 | AB6: =IFERROR(VLOOKUP(V6,'舰船数据-深海'!$A:$C,3,FALSE),) -> 0 | AC6: =IFERROR(VLOOKUP(W6,'舰船数据-深海'!$A:$C,3,FALSE),) -> 0 | AD6: =IFERROR(VLOOKUP(X6,'舰船数据-深海'!$A:$C,3,FALSE),) -> 0 | AE6: =IFERROR(VLOOKUP(Y6,'舰船数据-深海'!$A:$C,3,FALSE),) -> 0 | AM6: =IFERROR(VLOOKUP(AG6,'舰船数据-深海'!$A:$C,3,FALSE),) -> 0 | AN6: =IFERROR(VLOOKUP(AH6,'舰船数据-深海'!$A:$C,3,FALSE),) -> 0 | AO6: =IFERROR(VLOOKUP(AI6,'舰船数据-深海'!$A:$C,3,FALSE),) -> 0 | AP6: =IFERROR(VLOOKUP(AJ6,'舰船数据-深海'!$A:$C,3,FALSE),) -> 0 | AQ6: =IFERROR(VLOOKUP(AK6,'舰船数据-深海'!$A:$C,3,FALSE),) -> 0 | AR6: =IFERROR(VLOOKUP(AL6,'舰船数据-深海'!$A:$C,3,FALSE),) -> 0
A7: 00005 | B7: A | C7: NormalBattle | D7: 1 | E7: 0 | F7: 1 | G7: 00018 | H7: 00018 | I7: 00090 | J7: 00090 | K7: 00074 | L7: 00074 | M7: =IFERROR(VLOOKUP(G7,'舰船数据-深海'!$A:$C,3,FALSE),) -> 航母Ο级Ⅲ型 | N7: =IFERROR(VLOOKUP(H7,'舰船数据-深海'!$A:$C,3,FALSE),) -> 航母Ο级Ⅲ型 | O7: =IFERROR(VLOOKUP(I7,'舰船数据-深海'!$A:$C,3,FALSE),) -> 重巡Ω级Ⅱ型 | P7: =IFERROR(VLOOKUP(J7,'舰船数据-深海'!$A:$C,3,FALSE),) -> 重巡Ω级Ⅱ型 | Q7: =IFERROR(VLOOKUP(K7,'舰船数据-深海'!$A:$C,3,FALSE),) -> 驱逐Τ级Ⅱ型 | R7: =IFERROR(VLOOKUP(L7,'舰船数据-深海'!$A:$C,3,FALSE),) -> 驱逐Τ级Ⅱ型 | Z7: =IFERROR(VLOOKUP(T7,'舰船数据-深海'!$A:$C,3,FALSE),) -> 0 | AA7: =IFERROR(VLOOKUP(U7,'舰船数据-深海'!$A:$C,3,FALSE),) -> 0 | AB7: =IFERROR(VLOOKUP(V7,'舰船数据-深海'!$A:$C,3,FALSE),) -> 0 | AC7: =IFERROR(VLOOKUP(W7,'舰船数据-深海'!$A:$C,3,FALSE),) -> 0 | AD7: =IFERROR(VLOOKUP(X7,'舰船数据-深海'!$A:$C,3,FALSE),) -> 0 | AE7: =IFERROR(VLOOKUP(Y7,'舰船数据-深海'!$A:$C,3,FALSE),) -> 0 | AM7: =IFERROR(VLOOKUP(AG7,'舰船数据-深海'!$A:$C,3,FALSE),) -> 0 | AN7: =IFERROR(VLOOKUP(AH7,'舰船数据-深海'!$A:$C,3,FALSE),) -> 0 | AO7: =IFERROR(VLOOKUP(AI7,'舰船数据-深海'!$A:$C,3,FALSE),) -> 0 | AP7: =IFERROR(VLOOKUP(AJ7,'舰船数据-深海'!$A:$C,3,FALSE),) -> 0 | AQ7: =IFERROR(VLOOKUP(AK7,'舰船数据-深海'!$A:$C,3,FALSE),) -> 0 | AR7: =IFERROR(VLOOKUP(AL7,'舰船数据-深海'!$A:$C,3,FALSE),) -> 0
A8: 00006 | B8: D | C8: NormalBattle | D8: 2 | E8: 0 | F8: 1 | G8: 00087 | H8: 00087 | I8: 00091 | J8: 00091 | K8: 00090 | L8: 00090 | M8: =IFERROR(VLOOKUP(G8,'舰船数据-深海'!$A:$C,3,FALSE),) -> 战列Ψ级Ⅲ型 | N8: =IFERROR(VLOOKUP(H8,'舰船数据-深海'!$A:$C,3,FALSE),) -> 战列Ψ级Ⅲ型 | O8: =IFERROR(VLOOKUP(I8,'舰船数据-深海'!$A:$C,3,FALSE),) -> 重巡Ω级Ⅲ型 | P8: =IFERROR(VLOOKUP(J8,'舰船数据-深海'!$A:$C,3,FALSE),) -> 重巡Ω级Ⅲ型 | Q8: =IFERROR(VLOOKUP(K8,'舰船数据-深海'!$A:$C,3,FALSE),) -> 重巡Ω级Ⅱ型 | R8: =IFERROR(VLOOKUP(L8,'舰船数据-深海'!$A:$C,3,FALSE),) -> 重巡Ω级Ⅱ型 | Z8: =IFERROR(VLOOKUP(T8,'舰船数据-深海'!$A:$C,3,FALSE),) -> 0 | AA8: =IFERROR(VLOOKUP(U8,'舰船数据-深海'!$A:$C,3,FALSE),) -> 0 | AB8: =IFERROR(VLOOKUP(V8,'舰船数据-深海'!$A:$C,3,FALSE),) -> 0 | AC8: =IFERROR(VLOOKUP(W8,'舰船数据-深海'!$A:$C,3,FALSE),) -> 0 | AD8: =IFERROR(VLOOKUP(X8,'舰船数据-深海'!$A:$C,3,FALSE),) -> 0 | AE8: =IFERROR(VLOOKUP(Y8,'舰船数据-深海'!$A:$C,3,FALSE),) -> 0 | AM8: =IFERROR(VLOOKUP(AG8,'舰船数据-深海'!$A:$C,3,FALSE),) -> 0 | AN8: =IFERROR(VLOOKUP(AH8,'舰船数据-深海'!$A:$C,3,FALSE),) -> 0 | AO8: =IFERROR(VLOOKUP(AI8,'舰船数据-深海'!$A:$C,3,FALSE),) -> 0 | AP8: =IFERROR(VLOOKUP(AJ8,'舰船数据-深海'!$A:$C,3,FALSE),) -> 0 | AQ8: =IFERROR(VLOOKUP(AK8,'舰船数据-深海'!$A:$C,3,FALSE),) -> 0 | AR8: =IFERROR(VLOOKUP(AL8,'舰船数据-深海'!$A:$C,3,FALSE),) -> 0
A9: 00007 | B9: H | C9: NormalBattle | D9: 3 | E9: 0 | F9: 1 | G9: 00068 | H9: 00068 | I9: 00019 | J9: 00019 | K9: 00079 | L9: 00079 | M9: =IFERROR(VLOOKUP(G9,'舰船数据-深海'!$A:$C,3,FALSE),) -> 战巡Κ级Ⅳ型 | N9: =IFERROR(VLOOKUP(H9,'舰船数据-深海'!$A:$C,3,FALSE),) -> 战巡Κ级Ⅳ型 | O9: =IFERROR(VLOOKUP(I9,'舰船数据-深海'!$A:$C,3,FALSE),) -> 航母Ο级Ⅳ型 | P9: =IFERROR(VLOOKUP(J9,'舰船数据-深海'!$A:$C,3,FALSE),) -> 航母Ο级Ⅳ型 | Q9: =IFERROR(VLOOKUP(K9,'舰船数据-深海'!$A:$C,3,FALSE),) -> 潜艇Φ级Ⅲ型 | R9: =IFERROR(VLOOKUP(L9,'舰船数据-深海'!$A:$C,3,FALSE),) -> 潜艇Φ级Ⅲ型 | Z9: =IFERROR(VLOOKUP(T9,'舰船数据-深海'!$A:$C,3,FALSE),) -> 0 | AA9: =IFERROR(VLOOKUP(U9,'舰船数据-深海'!$A:$C,3,FALSE),) -> 0 | AB9: =IFERROR(VLOOKUP(V9,'舰船数据-深海'!$A:$C,3,FALSE),) -> 0 | AC9: =IFERROR(VLOOKUP(W9,'舰船数据-深海'!$A:$C,3,FALSE),) -> 0 | AD9: =IFERROR(VLOOKUP(X9,'舰船数据-深海'!$A:$C,3,FALSE),) -> 0 | AE9: =IFERROR(VLOOKUP(Y9,'舰船数据-深海'!$A:$C,3,FALSE),) -> 0 | AM9: =IFERROR(VLOOKUP(AG9,'舰船数据-深海'!$A:$C,3,FALSE),) -> 0 | AN9: =IFERROR(VLOOKUP(AH9,'舰船数据-深海'!$A:$C,3,FALSE),) -> 0 | AO9: =IFERROR(VLOOKUP(AI9,'舰船数据-深海'!$A:$C,3,FALSE),) -> 0 | AP9: =IFERROR(VLOOKUP(AJ9,'舰船数据-深海'!$A:$C,3,FALSE),) -> 0 | AQ9: =IFERROR(VLOOKUP(AK9,'舰船数据-深海'!$A:$C,3,FALSE),) -> 0 | AR9: =IFERROR(VLOOKUP(AL9,'舰船数据-深海'!$A:$C,3,FALSE),) -> 0
A10: 00101 | B10: N | C10: NormalBattle | D10: 5 | E10: 0 | F10: 4 | G10: 01041 | H10: 01042 | I10: 01043 | J10: 01044 | K10: 01045 | L10: 01046 | M10: =IFERROR(VLOOKUP(G10,'舰船数据-深海'!$A:$C,3,FALSE),) -> Hindenburg | N10: =IFERROR(VLOOKUP(H10,'舰船数据-深海'!$A:$C,3,FALSE),) -> Peter Strasser | O10: =IFERROR(VLOOKUP(I10,'舰船数据-深海'!$A:$C,3,FALSE),) -> Leopold(K5) | P10: =IFERROR(VLOOKUP(J10,'舰船数据-深海'!$A:$C,3,FALSE),) -> Bismarck | Q10: =IFERROR(VLOOKUP(K10,'舰船数据-深海'!$A:$C,3,FALSE),) -> Prinz Eugen | R10: =IFERROR(VLOOKUP(L10,'舰船数据-深海'!$A:$C,3,FALSE),) -> U-99 | S10: 2 | T10: 01041 | U10: 01042 | V10: 01043 | W10: 01044 | X10: 01045 | Y10: 01046 | Z10: =IFERROR(VLOOKUP(T10,'舰船数据-深海'!$A:$C,3,FALSE),) -> Hindenburg | AA10: =IFERROR(VLOOKUP(U10,'舰船数据-深海'!$A:$C,3,FALSE),) -> Peter Strasser | AB10: =IFERROR(VLOOKUP(V10,'舰船数据-深海'!$A:$C,3,FALSE),) -> Leopold(K5) | AC10: =IFERROR(VLOOKUP(W10,'舰船数据-深海'!$A:$C,3,FALSE),) -> Bismarck | AD10: =IFERROR(VLOOKUP(X10,'舰船数据-深海'!$A:$C,3,FALSE),) -> Prinz Eugen | AE10: =IFERROR(VLOOKUP(Y10,'舰船数据-深海'!$A:$C,3,FALSE),) -> U-99 | AF10: 5 | AG10: 01041 | AH10: 01042 | AI10: 01043 | AJ10: 01044 | AK10: 01045 | AL10: 01046 | AM10: =IFERROR(VLOOKUP(AG10,'舰船数据-深海'!$A:$C,3,FALSE),) -> Hindenburg | AN10: =IFERROR(VLOOKUP(AH10,'舰船数据-深海'!$A:$C,3,FALSE),) -> Peter Strasser | AO10: =IFERROR(VLOOKUP(AI10,'舰船数据-深海'!$A:$C,3,FALSE),) -> Leopold(K5) | AP10: =IFERROR(VLOOKUP(AJ10,'舰船数据-深海'!$A:$C,3,FALSE),) -> Bismarck | AQ10: =IFERROR(VLOOKUP(AK10,'舰船数据-深海'!$A:$C,3,FALSE),) -> Prinz Eugen | AR10: =IFERROR(VLOOKUP(AL10,'舰船数据-深海'!$A:$C,3,FALSE),) -> U-99
A11: 00201 | B11: A | C11: NormalBattle | D11: 1 | E11: 0 | F11: 2 | G11: 00046 | H11: 00092 | I11: 00092 | J11: 00096 | K11: 00076 | L11: 00203 | M11: =IFERROR(VLOOKUP(G11,'舰船数据-深海'!$A:$C,3,FALSE),) -> 战列Λ级Ⅳ型 | N11: =IFERROR(VLOOKUP(H11,'舰船数据-深海'!$A:$C,3,FALSE),) -> 重巡Ω级Ⅳ型 | O11: =IFERROR(VLOOKUP(I11,'舰船数据-深海'!$A:$C,3,FALSE),) -> 重巡Ω级Ⅳ型 | P11: =IFERROR(VLOOKUP(J11,'舰船数据-深海'!$A:$C,3,FALSE),) -> 轻巡ei级Ⅳ型 | Q11: =IFERROR(VLOOKUP(K11,'舰船数据-深海'!$A:$C,3,FALSE),) -> 驱逐Τ级Ⅳ型 | R11: =IFERROR(VLOOKUP(L11,'舰船数据-深海'!$A:$C,3,FALSE),) -> 防驱be级Ⅳ型
A12: 00202 | B12: B | C12: NormalBattle | D12: 1 | E12: 0 | F12: 1 | G12: 00046 | H12: 00034 | I12: 00076 | J12: 00096 | K12: 00076 | L12: 00096 | M12: =IFERROR(VLOOKUP(G12,'舰船数据-深海'!$A:$C,3,FALSE),) -> 战列Λ级Ⅳ型 | N12: =IFERROR(VLOOKUP(H12,'舰船数据-深海'!$A:$C,3,FALSE),) -> 轻母Ξ级Ⅳ型 | O12: =IFERROR(VLOOKUP(I12,'舰船数据-深海'!$A:$C,3,FALSE),) -> 驱逐Τ级Ⅳ型 | P12: =IFERROR(VLOOKUP(J12,'舰船数据-深海'!$A:$C,3,FALSE),) -> 轻巡ei级Ⅳ型 | Q12: =IFERROR(VLOOKUP(K12,'舰船数据-深海'!$A:$C,3,FALSE),) -> 驱逐Τ级Ⅳ型 | R12: =IFERROR(VLOOKUP(L12,'舰船数据-深海'!$A:$C,3,FALSE),) -> 轻巡ei级Ⅳ型
A13: 00203 | B13: C | C13: NormalBattle | D13: 1 | E13: 0 | F13: 1 | G13: 00046 | H13: 00034 | I13: 00092 | J13: 00092 | K13: 00076 | L13: 00076 | M13: =IFERROR(VLOOKUP(G13,'舰船数据-深海'!$A:$C,3,FALSE),) -> 战列Λ级Ⅳ型 | N13: =IFERROR(VLOOKUP(H13,'舰船数据-深海'!$A:$C,3,FALSE),) -> 轻母Ξ级Ⅳ型 | O13: =IFERROR(VLOOKUP(I13,'舰船数据-深海'!$A:$C,3,FALSE),) -> 重巡Ω级Ⅳ型 | P13: =IFERROR(VLOOKUP(J13,'舰船数据-深海'!$A:$C,3,FALSE),) -> 重巡Ω级Ⅳ型 | Q13: =IFERROR(VLOOKUP(K13,'舰船数据-深海'!$A:$C,3,FALSE),) -> 驱逐Τ级Ⅳ型 | R13: =IFERROR(VLOOKUP(L13,'舰船数据-深海'!$A:$C,3,FALSE),) -> 驱逐Τ级Ⅳ型
A14: 00204 | B14: D | C14: NormalBattle | D14: 2 | E14: 1 | F14: 2 | G14: 00046 | H14: 00046 | I14: 00068 | J14: 00092 | K14: 00096 | L14: 00076 | M14: =IFERROR(VLOOKUP(G14,'舰船数据-深海'!$A:$C,3,FALSE),) -> 战列Λ级Ⅳ型 | N14: =IFERROR(VLOOKUP(H14,'舰船数据-深海'!$A:$C,3,FALSE),) -> 战列Λ级Ⅳ型 | O14: =IFERROR(VLOOKUP(I14,'舰船数据-深海'!$A:$C,3,FALSE),) -> 战巡Κ级Ⅳ型 | P14: =IFERROR(VLOOKUP(J14,'舰船数据-深海'!$A:$C,3,FALSE),) -> 重巡Ω级Ⅳ型 | Q14: =IFERROR(VLOOKUP(K14,'舰船数据-深海'!$A:$C,3,FALSE),) -> 轻巡ei级Ⅳ型 | R14: =IFERROR(VLOOKUP(L14,'舰船数据-深海'!$A:$C,3,FALSE),) -> 驱逐Τ级Ⅳ型
A15: 00205 | B15: F | C15: NormalBattle | D15: 2 | E15: 0 | F15: 1 | G15: 00046 | H15: 00068 | I15: 00034 | J15: 00092 | K15: 00092 | L15: 00096 | M15: =IFERROR(VLOOKUP(G15,'舰船数据-深海'!$A:$C,3,FALSE),) -> 战列Λ级Ⅳ型 | N15: =IFERROR(VLOOKUP(H15,'舰船数据-深海'!$A:$C,3,FALSE),) -> 战巡Κ级Ⅳ型 | O15: =IFERROR(VLOOKUP(I15,'舰船数据-深海'!$A:$C,3,FALSE),) -> 轻母Ξ级Ⅳ型 | P15: =IFERROR(VLOOKUP(J15,'舰船数据-深海'!$A:$C,3,FALSE),) -> 重巡Ω级Ⅳ型 | Q15: =IFERROR(VLOOKUP(K15,'舰船数据-深海'!$A:$C,3,FALSE),) -> 重巡Ω级Ⅳ型 | R15: =IFERROR(VLOOKUP(L15,'舰船数据-深海'!$A:$C,3,FALSE),) -> 轻巡ei级Ⅳ型
A16: 00206 | B16: G | C16: NormalBattle | D16: 2 | E16: 0 | F16: 2 | G16: 00046 | H16: 00046 | I16: 00092 | J16: 00034 | K16: 00096 | L16: 00096 | M16: =IFERROR(VLOOKUP(G16,'舰船数据-深海'!$A:$C,3,FALSE),) -> 战列Λ级Ⅳ型 | N16: =IFERROR(VLOOKUP(H16,'舰船数据-深海'!$A:$C,3,FALSE),) -> 战列Λ级Ⅳ型 | O16: =IFERROR(VLOOKUP(I16,'舰船数据-深海'!$A:$C,3,FALSE),) -> 重巡Ω级Ⅳ型 | P16: =IFERROR(VLOOKUP(J16,'舰船数据-深海'!$A:$C,3,FALSE),) -> 轻母Ξ级Ⅳ型 | Q16: =IFERROR(VLOOKUP(K16,'舰船数据-深海'!$A:$C,3,FALSE),) -> 轻巡ei级Ⅳ型 | R16: =IFERROR(VLOOKUP(L16,'舰船数据-深海'!$A:$C,3,FALSE),) -> 轻巡ei级Ⅳ型
A17: 00207 | B17: H | C17: NormalBattle | D17: 3 | E17: 0 | F17: 1 | G17: 00046 | H17: 00046 | I17: 00046 | J17: 00092 | K17: 00092 | L17: 00076 | M17: =IFERROR(VLOOKUP(G17,'舰船数据-深海'!$A:$C,3,FALSE),) -> 战列Λ级Ⅳ型 | N17: =IFERROR(VLOOKUP(H17,'舰船数据-深海'!$A:$C,3,FALSE),) -> 战列Λ级Ⅳ型 | O17: =IFERROR(VLOOKUP(I17,'舰船数据-深海'!$A:$C,3,FALSE),) -> 战列Λ级Ⅳ型 | P17: =IFERROR(VLOOKUP(J17,'舰船数据-深海'!$A:$C,3,FALSE),) -> 重巡Ω级Ⅳ型 | Q17: =IFERROR(VLOOKUP(K17,'舰船数据-深海'!$A:$C,3,FALSE),) -> 重巡Ω级Ⅳ型 | R17: =IFERROR(VLOOKUP(L17,'舰船数据-深海'!$A:$C,3,FALSE),) -> 驱逐Τ级Ⅳ型
A18: 00208 | B18: I | C18: MidPoint | D18: 4 | E18: 0 | M18: =IFERROR(VLOOKUP(G18,'舰船数据-深海'!$A:$C,3,FALSE),) -> 0 | N18: =IFERROR(VLOOKUP(H18,'舰船数据-深海'!$A:$C,3,FALSE),) -> 0 | O18: =IFERROR(VLOOKUP(I18,'舰船数据-深海'!$A:$C,3,FALSE),) -> 0 | P18: =IFERROR(VLOOKUP(J18,'舰船数据-深海'!$A:$C,3,FALSE),) -> 0 | Q18: =IFERROR(VLOOKUP(K18,'舰船数据-深海'!$A:$C,3,FALSE),) -> 0 | R18: =IFERROR(VLOOKUP(L18,'舰船数据-深海'!$A:$C,3,FALSE),) -> 0
A19: 00209 | B19: J | C19: MidPoint | D19: 2 | E19: 0 | M19: =IFERROR(VLOOKUP(G19,'舰船数据-深海'!$A:$C,3,FALSE),) -> 0 | N19: =IFERROR(VLOOKUP(H19,'舰船数据-深海'!$A:$C,3,FALSE),) -> 0 | O19: =IFERROR(VLOOKUP(I19,'舰船数据-深海'!$A:$C,3,FALSE),) -> 0 | P19: =IFERROR(VLOOKUP(J19,'舰船数据-深海'!$A:$C,3,FALSE),) -> 0 | Q19: =IFERROR(VLOOKUP(K19,'舰船数据-深海'!$A:$C,3,FALSE),) -> 0 | R19: =IFERROR(VLOOKUP(L19,'舰船数据-深海'!$A:$C,3,FALSE),) -> 0
A20: 00210 | B20: L | C20: MidPoint | D20: 4 | E20: 0 | M20: =IFERROR(VLOOKUP(G20,'舰船数据-深海'!$A:$C,3,FALSE),) -> 0 | N20: =IFERROR(VLOOKUP(H20,'舰船数据-深海'!$A:$C,3,FALSE),) -> 0 | O20: =IFERROR(VLOOKUP(I20,'舰船数据-深海'!$A:$C,3,FALSE),) -> 0 | P20: =IFERROR(VLOOKUP(J20,'舰船数据-深海'!$A:$C,3,FALSE),) -> 0 | Q20: =IFERROR(VLOOKUP(K20,'舰船数据-深海'!$A:$C,3,FALSE),) -> 0 | R20: =IFERROR(VLOOKUP(L20,'舰船数据-深海'!$A:$C,3,FALSE),) -> 0
A21: 00211 | B21: M | C21: NormalBattle | D21: 3 | E21: 0 | F21: 1 | G21: 00046 | H21: 00046 | I21: 00046 | J21: 00096 | K21: 00096 | L21: 00096 | M21: =IFERROR(VLOOKUP(G21,'舰船数据-深海'!$A:$C,3,FALSE),) -> 战列Λ级Ⅳ型 | N21: =IFERROR(VLOOKUP(H21,'舰船数据-深海'!$A:$C,3,FALSE),) -> 战列Λ级Ⅳ型 | O21: =IFERROR(VLOOKUP(I21,'舰船数据-深海'!$A:$C,3,FALSE),) -> 战列Λ级Ⅳ型 | P21: =IFERROR(VLOOKUP(J21,'舰船数据-深海'!$A:$C,3,FALSE),) -> 轻巡ei级Ⅳ型 | Q21: =IFERROR(VLOOKUP(K21,'舰船数据-深海'!$A:$C,3,FALSE),) -> 轻巡ei级Ⅳ型 | R21: =IFERROR(VLOOKUP(L21,'舰船数据-深海'!$A:$C,3,FALSE),) -> 轻巡ei级Ⅳ型
A22: 00212 | B22: O | C22: NormalBattle | D22: 3 | E22: 0 | F22: 1 | G22: 00088 | H22: 00068 | I22: 00068 | J22: 00034 | K22: 00034 | L22: 00096 | M22: =IFERROR(VLOOKUP(G22,'舰船数据-深海'!$A:$C,3,FALSE),) -> 战列Ψ级Ⅳ型 | N22: =IFERROR(VLOOKUP(H22,'舰船数据-深海'!$A:$C,3,FALSE),) -> 战巡Κ级Ⅳ型 | O22: =IFERROR(VLOOKUP(I22,'舰船数据-深海'!$A:$C,3,FALSE),) -> 战巡Κ级Ⅳ型 | P22: =IFERROR(VLOOKUP(J22,'舰船数据-深海'!$A:$C,3,FALSE),) -> 轻母Ξ级Ⅳ型 | Q22: =IFERROR(VLOOKUP(K22,'舰船数据-深海'!$A:$C,3,FALSE),) -> 轻母Ξ级Ⅳ型 | R22: =IFERROR(VLOOKUP(L22,'舰船数据-深海'!$A:$C,3,FALSE),) -> 轻巡ei级Ⅳ型
A23: 00213 | B23: R | C23: NormalBattle | D23: 5 | E23: 0 | F23: 4 | G23: 01047 | H23: 01048 | I23: 01050 | J23: 01051 | K23: 01052 | L23: 01054 | M23: =IFERROR(VLOOKUP(G23,'舰船数据-深海'!$A:$C,3,FALSE),) -> 111 | N23: =IFERROR(VLOOKUP(H23,'舰船数据-深海'!$A:$C,3,FALSE),) -> Yamato | O23: =IFERROR(VLOOKUP(I23,'舰船数据-深海'!$A:$C,3,FALSE),) -> Musashi | P23: =IFERROR(VLOOKUP(J23,'舰船数据-深海'!$A:$C,3,FALSE),) -> Cyou-Yamato | Q23: =IFERROR(VLOOKUP(K23,'舰船数据-深海'!$A:$C,3,FALSE),) -> Akagi&Kaga | R23: =IFERROR(VLOOKUP(L23,'舰船数据-深海'!$A:$C,3,FALSE),) -> 13 Class Battleship
